Workbook
Name TAB_AFP: TASAS!$B$5:$I$13
Name TAB_AFP: #REF!

Sheet TASAS
E1: https://www.sbs.gob.pe/app/spp/empleadores/comisiones_spp/Paginas/comision_prima.aspx
A2: Al mes de devengue 2020/06
A3: ITEM | B3: AFP | C3: ONP | D3: COMISION MIXTA | F3: PRIMA SEGURO | G3: APORTE OBLIGATORIO | H3: Remuneración Máxima Asegurable | I3: TOTAL
D4: COMISION SOBRE LA REMUNERACION (FLUJO ) | E4: COMISION ANUAL SOBRE SALDO
A5: 1 | B5: HABITAT MIXTA | D5: 0.0038 | E5: 0.0125 | F5: 0.0174 | G5: 0.1 | H5: 9665.33 | I5: =SUM(D5,F5,G5) -> 0.1212
A6: =A5+1 -> 2 | B6: HABITAT SUELDO | D6: 0.0147 | E6: 0.0023 | F6: 0.0174 | G6: 0.1 | I6: =SUM(D6,F6,G6) -> 0.1321
A7: =A6+1 -> 3 | B7: INTEGRA MIXTA | D7: 0.0056 | E7: 0.012 | F7: 0.0174 | G7: 0.1 | H7: 9665.33 | I7: =SUM(D7,F7,G7) -> 0.123
A8: =A7+1 -> 4 | B8: INTEGRA SUELDO | D8: 0.0155 | F8: 0.0174 | G8: 0.1 | I8: =SUM(D8,F8,G8) -> 0.1329
A9: =A8+1 -> 5 | B9: PRIMA MIXTA | D9: 0.0018 | E9: 0.0125 | F9: 0.0174 | G9: 0.1 | H9: 9665.33 | I9: =SUM(D9,F9,G9) -> 0.1192
A10: =A9+1 -> 6 | B10: PRIMA SUELDO | D10: 0.016 | F10: 0.0174 | G10: 0.1 | I10: =SUM(D10,F10,G10) -> 0.1334
A11: =A10+1 -> 7 | B11: PROFUTURO MIXTA | D11: 0.0067 | E11: 0.012 | F11: 0.0174 | G11: 0.1 | H11: 9665.33 | I11: =SUM(D11,F11,G11) -> 0.1241
A12: =A11+1 -> 8 | B12: PROFUTURO SUELDO | D12: 0.0169 | F12: 0.0174 | G12: 0.1 | I12: =SUM(D12,F12,G12) -> 0.1343
A13: =A12+1 -> 9 | B13: ONP | C13: 0.13 | G13: 0.13 | H13: 0 | I13: =SUM(D13,F13,G13) -> 0.13
B16: Al mes de devengue 2020-05 1/
B17: AFP | C17: COMISIÓN FIJA 2/ | D17: COMISIÓN SOBRE FLUJO | E17: COMISIÓN MIXTA5/ | G17: PRIMA DE SEGUROS (%) 4/ | H17: APORTE OBLIGATORIO AL FONDO DE PENSIONES | I17: REMUNERACIÓN MÁXIMA ASEGURABLE | K17: PRIMA SUELDO
K18: PROFUTURO MIXTA
E19: COMISIÓN | F19: COMISIÓN | K19: PROFUTURO MIXTA
D20: (% Remuneración Bruta Mensual) | E20: SOBRE FLUJO | F20: ANUAL SOBRE | G20: (% Remuneración Bruta Mensual) | H20: (% Remuneración Bruta Mensual) | K20: PROFUTURO SUELDO
E21: (% Remuneración Bruta Mensual) | F21: SALDO 3/ | K21: INTEGRA SUELDO
B22: HABITAT | D22: 0.0147 | E22: 0.0038 | F22: 0.0125 | G22: 0.0135 | H22: 0.1 | I22: 9788.95 | K22: PROFUTURO SUELDO
B23: INTEGRA | D23: 0.0155 | E23: 0 | F23: 0.0082 | G23: 0.0135 | H23: 0.1 | I23: 9788.95
B24: PRIMA | D24: 0.016 | E24: 0.0018 | F24: 0.0125 | G24: 0.0135 | H24: 0.1 | I24: 9788.95
B25: PROFUTURO | D25: 0.0169 | E25: 0.0067 | F25: 0.012 | G25: 0.0135 | H25: 0.1 | I25: 9788.95

Sheet quinta categoria
C3: Excel para calcular el descuento por el impuesto a la Renta de quinta categoría
C5: Proyección de ingresos brutos anuales | F5: S/. | G5: 71238.46
C6: Monto de 7 UIT descontable | F6: S/. | G6: =+G18*7 -> 38500
C7: Renta neta gravable de impuesto de quinta | F7: S/. | G7: =+IF((G5-G6)<0,0,(G5-G6)) -> 32738.46
C9: Escala UIT | D9: Tasas | E9: Máximos en S/. | F9: Monto afecto en S/. | G9: Impuesto en S/.
C10: Hasta 5 UIT | D10: 0.08 | E10: =5*G18 -> 27500 | F10: =+IF(G5<=(G6),0,(IF(G7<=E10,G7,E10))) -> 27500 | G10: =+F10*D10 -> 2200
C11: Mas de 5 UIT hasta 20 UIT | D11: 0.14 | E11: =20*G18 -> 110000 | F11: =+IF((G7-F10)<=0,0,(IF(G7<=E11,G7-F10,E11-F10))) -> 5238.46 | G11: =+F11*D11 -> 733.3844
C12: Mas de 20 UIT hasta 35 UIT | D12: 0.17 | E12: =35*G18 -> 192500 | F12: =+IF((G7-(F10+F11))<=0,0,(IF(G7<=E12,G7-(F10+F11),E12-F11-F10))) -> 0 | G12: =+F12*D12 -> 0
C13: Mas de 35 UIT hasta 45 UIT | D13: 0.2 | E13: =45*G18 -> 247500 | F13: =+IF((G7-(F10+F11+F12))<=0,0,(IF(G7<=E13,G7-(F10+F11+F12),E13-F12-F11-F10))) -> 0 | G13: =+F13*D13 -> 0
C14: Mas de 45 UIT | D14: 0.3 | E14: =+CONCATENATE("> ",E13) -> > 247500 | F14: =+IF(G7>E13,G7-E13,0) -> 0 | G14: =+F14*D14 -> 0
C15: Impuesto a la Renta a pagar por el año en curso | F15: =+F14+F13+F10 -> 27500 | G15: =+SUM(G10:G14) -> 2933.3844
C17: Retención Mensual aproximada que se realiza al trabajador | G17: =+G15/12 -> 244.4487
C18: Unidad Impositiva Tributaria (UIT) del año en curso | G18: 5500

Sheet Tabla
J2: COMISIÓN MIXTA (5)
F3: % DCTO POR REMUNER | G3: APORTE FONDO DE PENSIONES | H3: PRIMA DE SEGURO (4) | I3: COMISION SOBRE REMUNERACIÓN MENSUAL | J3: COMISION SOBRE REMUNERACIÓN FLUJO(% remuneración bruta mensual) | K3: COMISION ANUAL SOBRE SALDO (3) | L3: % DCTO POR COMISIÓN MIXTA | M3: % DCTO POR SALDO
C4: REG NORMAL | D4: =+B6 -> 11238.83 | E4: INT | F4: =+G4+H4+I4 -> 0.1329 | G4: 0.1 | H4: 0.0174 | I4: 0.0155 | J4: 0 | K4: 0.0079 | L4: =+G4+H4+J4 -> 0.1174 | M4: =+G4+H4+K4 -> 0.1253
C5: REG NORMAL | E5: PRI | F5: =+G5+H5+I5 -> 0.1334 | G5: 0.1 | H5: 0.0174 | I5: 0.016 | J5: 0.0018 | K5: 0.0125 | L5: =+G5+H5+J5 -> 0.1192 | M5: =+G5+H5+K5 -> 0.1299
B6: 11238.83 | C6: REG NORMAL | E6: PRO | F6: =+G6+H6+I6 -> 0.1343 | G6: 0.1 | H6: 0.0174 | I6: 0.0169 | J6: 0.0028 | K6: 0.012 | L6: =+G6+H6+J6 -> 0.1202 | M6: =+G6+H6+K6 -> 0.1294
B7: oct - dic 2022} | C7: REG NORMAL | E7: HAB | F7: =+G7+H7+I7 -> 0.1321 | G7: 0.1 | H7: 0.0174 | I7: 0.0147 | J7: 0.0023 | K7: 0.0125 | L7: =+G7+H7+J7 -> 0.1197 | M7: =+G7+H7+K7 -> 0.1299
B8: Monto limite gtos. Sepelio
B9: 4554.41
B10: ASIGNACIÓN FAMILIAR | D10: RMV | E10: % | F10: TOTAL
D11: =930+95 -> 1025 | E11: 0.1 | F11: =+D11*E11 -> 102.5

Sheet 1RA QUINCENA JUNIO 26
B1: LEYENDA | AJ1: 1RA QUINCENA JUNIO 2026
B2: CESADOS | AY2: HASTA 5 UIT | AZ2: 0.08
B3: VACACIONES | C3: 30 | AY3: DE 5 A 20 UIT | AZ3: 0.14
B4: COLECTORA | C4: 46174 | Q4: DIAS LABORADOS | AY4: DE 20 A 35 UIT | AZ4: 0.17
B5: LICENCIA | AY5: DE 35 A 45 UIT | AZ5: 0.2
A6: 1 | B6: =+A6+1 -> 2 | C6: =+B6+1 -> 3 | D6: =+C6+1 -> 4 | E6: =+D6+1 -> 5 | F6: =+E6+1 -> 6 | G6: =+F6+1 -> 7 | H6: =+G6+1 -> 8 | I6: =+H6+1 -> 9 | ... BJ6: =+BI6+1 -> 62
A7: N° | B7: APELLIDO Y NOMBRES | C7: FECHA DE NACIM. | D7: DNI | E7: FECHA INGRESO | F7: FECHA DE CESE | G7: GENERO | H7: TIPO DE CONTRATO | I7: CATEGORIA OCUPACIONAL | J7: ONP | K7: SCTR | L7: SENATI | M7: COD AFP | N7: AREA | O7: CARGO | P7: SUELDO BASICO | Q7: ASIG FAM | R7: MOVILIDAD | S7: POR FUERA | T7: TOTAL MENSUAL | U7: DIAS TRABAJADOS | V7: DM | W7: DIAS FALTO | Y7: TARDANZAS | AA7: PAGO | AB7: LICENCIA | AC7: SUBSIDIO | AD7: LIQ VACACIONES | AG7: INCENTIVOS | AH7: LICENCIA HIJO ENFERMO | AJ7: REMUNERACIÓN QUINCENAL | AK7: SABADOS | AM7: HORAS EXTRAS | AO7: DOMINGOS Y FERIADOS | AQ7: INCENTIVO POR PRODUCION | AR7: TOTAL MOVIL QUINCENAL | AS7: SISTEMA DE PENSIONES | AV7: ONP | AW7: AFP PRIMA | AZ7: DSCTO AFP | BA7: RETENCION AFP/ONP | BB7: RTA. 5TA CATEG | BC7: NETO A PAGAR | BD7: ESSALUD | BE7: SCTR PENSIÓN | BF7: SCTR SALUD | BG7: SVL | BH7: ADELANTOS/PRESTA | BI7: REINTEGRO | BJ7: A PAGAR 15/06/26
W8: CANT | X8: DESCUENTO | Y8: CANT | Z8: DESCUENTO | AA8: GRAT | AD8: DIAS | AE8: MONTO | AF8: FINAL | AH8: CANT | AI8: DESCUENTO | AK8: CANTIDA | AL8: MONTO | AM8: CANT. | AN8: MONTO | AO8: CANTIDA | AP8: MONTO | AT8: COM | AV8: 0.13 | AW8: 0.1 | AX8: COMISION | AY8: PRIMA | BD8: 0.09 | BE8: 0.0214 | BG8: DL 688
A10: 1 | B10: CISNEROS PACOTAYPE KEVIN | D10: 71246290 | E10: 46143 | G10: MASCULINO | H10: A PLAZO FIJO | I10: EMPLEADO | J10: NO | K10: SI | L10: NO | N10: PRODUCCION | O10: INGENIERO | P10: 4500 | T10: =P10+Q10+R10+S10 -> 4500 | U10: ='HOJA RXH'!AH6 -> 8 | W10: ='HOJA RXH'!Z6 -> 7 | X10: =((P10+Q10)/$C$3)*W10 -> 1050 | Y10: ='HOJA RXH'!AD6 -> 0 | Z10: =(T10/30/8/60*Y10) -> 0 | AC10: =(P10/30)*V10 -> 0 | AH10: ='HOJA RXH'!V6 -> 0 | AJ10: =(((P10+Q10)/30)*U10)-Z10+AA10+AB10+AC10+AF10+AG10+AI10 -> 1200 | AK10: ='HOJA RXH'!J6 -> 0 | AL10: =T10/30*AK10 -> 0 | AM10: ='HOJA RXH'!F6 -> 5 | AN10: =T10/30/10*AM10 -> 75 | AO10: ='HOJA RXH'!N6 -> 0 | AP10: =T10/30*AO10 -> 0 | AQ10: 0 | AR10: =((R10/$C$3)*(U10-V10))+AL10+AP10+AN10+AQ10 -> 75 | AS10: INTEGRA MIXTA | AT10: 0 | AU10: 0.0137 | AV10: =IF(AS10="ONP",VLOOKUP(AS10,TASAS!TAB_AFP,8,0)*AJ10,0) -> 0 | AW10: =IF(AS10<>"ONP",AJ10*$AW$8,0) -> 120 | AX10: =IF(AS10<>"ONP",AJ10*AT10,0) -> 0 | AY10: =IF(AU10<>"ONP",AJ10*AU10,0) -> 16.44 | AZ10: =+AX10+AY10+AW10 -> 136.44 | BA10: =+AZ10+AV10 -> 136.44 | BC10: =AJ10+AR10-BA10-BB10 -> 1138.56 | BD10: =ROUND(AJ10*$BD$8,2) -> 108 | BE10: =IF(K10="SI",AJ10*2.14%,0) -> 25.68 | BG10: =+P10*0.54% -> 24.3 | BJ10: =BC10-BH10+BI10 -> 1138.56
A11: 2 | B11: CISNEROS SUMA, ANDRES JUAN | D11: 9594305 | E11: 45413 | G11: MASCULINO | H11: MYPE INDETERM | I11: EMPLEADO | J11: NO | K11: SI | L11: NO | M11: 554671ACSNA9 | N11: ADMINISTRACIÓN | O11: GERENTE | P11: 2530 | Q11: 113 | R11: 750 | T11: =P11+Q11+R11+S11 -> 3393 | U11: ='HOJA RXH'!AH7 -> 15 | W11: ='HOJA RXH'!Z7 -> 0 | X11: =((P11+Q11)/$C$3)*W11 -> 0 | Y11: ='HOJA RXH'!AD7 -> 60 | Z11: =(T11/30/8/60*Y11) -> 14.1375 | AC11: =(P11/30)*V11 -> 0 | AH11: ='HOJA RXH'!V7 -> 0 | AJ11: =(((P11+Q11)/30)*U11)-Z11+AA11+AB11+AC11+AF11+AG11+AI11 -> 1307.3625 | AK11: ='HOJA RXH'!J7 -> 0 | AL11: =T11/30*AK11 -> 0 | AM11: ='HOJA RXH'!F7 -> 0 | AN11: =T11/30/10*AM11 -> 0 | AO11: ='HOJA RXH'!N7 -> 0 | AP11: =T11/30*AO11 -> 0 | AQ11: 0 | AR11: =((R11/$C$3)*(U11-V11))+AL11+AP11+AN11+AQ11 -> 375 | AS11: PRIMA MIXTA | AT11: 0 | AU11: 0.0137 | AV11: =IF(AS11="ONP",VLOOKUP(AS11,TASAS!TAB_AFP,8,0)*AJ11,0) -> 0 | AW11: =IF(AS11<>"ONP",AJ11*$AW$8,0) -> 130.73625 | AX11: =IF(AS11<>"ONP",AJ11*AT11,0) -> 0 | AY11: =IF(AU11<>"ONP",AJ11*AU11,0) -> 17.910866 | AZ11: =+AX11+AY11+AW11 -> 148.64712 | BA11: =+AZ11+AV11 -> 148.64712 | BC11: =AJ11+AR11-BA11-BB11 -> 1533.7154 | BD11: =ROUND(AJ11*$BD$8,2) -> 117.66 | BE11: =IF(K11="SI",AJ11*2.14%,0) -> 27.977558 | BG11: =+P11*0.54% -> 13.662 | BJ11: =BC11-BH11+BI11 -> 1533.7154
A12: 3 | B12: CISNEROS SUMA, EDGAR | C12: 28322 | D12: 28316078 | E12: 43983 | G12: MASCULINO | H12: MYPE INDETERM | I12: EMPLEADO | J12: NO | K12: SI | L12: NO | M12: 583201ECSNA0 | N12: PRODUCCION | O12: SUPERVISOR DE PRODUCCION | P12: 4000 | Q12: 113 | R12: 1000 | T12: =P12+Q12+R12+S12 -> 5113 | U12: ='HOJA RXH'!AH8 -> 15 | W12: ='HOJA RXH'!Z8 -> 0 | X12: =((P12+Q12)/$C$3)*W12 -> 0 | Y12: ='HOJA RXH'!AD8 -> 0 | Z12: =(T12/30/8/60*Y12) -> 0 | AH12: ='HOJA RXH'!V8 -> 0 | AJ12: =(((P12+Q12)/30)*U12)-Z12+AA12+AB12+AC12+AF12+AG12+AI12 -> 2056.5 | AK12: ='HOJA RXH'!J8 -> 2 | AL12: =T12/30*AK12 -> 340.86667 | AM12: ='HOJA RXH'!F8 -> 0 | AN12: =T12/30/10*AM12 -> 0 | AO12: ='HOJA RXH'!N8 -> 0 | AP12: =T12/30*AO12 -> 0 | AQ12: 0 | AR12: =((R12/$C$3)*(U12-V12))+AL12+AP12+AN12+AQ12 -> 840.86667 | AS12: PROFUTURO FLUJO | AT12: 0.0169 | AU12: 0.0137 | AV12: =IF(AS12="ONP",VLOOKUP(AS12,TASAS!TAB_AFP,8,0)*AJ12,0) -> 0 | AW12: =IF(AS12<>"ONP",AJ12*$AW$8,0) -> 205.65 | AX12: =IF(AS12<>"ONP",AJ12*AT12,0) -> 34.75485 | AY12: =IF(AU12<>"ONP",AJ12*AU12,0) -> 28.17405 | AZ12: =+AX12+AY12+AW12 -> 268.5789 | BA12: =+AZ12+AV12 -> 268.5789 | BC12: =AJ12+AR12-BA12-BB12 -> 2628.7878 | BD12: =ROUND(AJ12*$BD$8,2) -> 185.09 | BE12: =IF(K12="SI",AJ12*2.14%,0) -> 44.0091 | BG12: =+P12*0.54% -> 21.6 | BJ12: =BC12-BH12+BI12 -> 2628.7878
A13: 4 | B13: CORI ADAN RUTBEL | C13: 22411 | D13: 6596301 | E13: 40269 | G13: MASCULINO | H13: INDETERMINADO | I13: OBRERO | J13: NO | K13: SI | L13: NO | M13: 224091RCAIN8 | N13: AUTOPARTES | O13: TORNERO | P13: 1130 | Q13: 0 | R13: 600 | T13: =P13+Q13+R13+S13 -> 1730 | U13: ='HOJA RXH'!AH9 -> 14 | W13: ='HOJA RXH'!Z9 -> 1 | X13: =((P13+Q13)/$C$3)*W13 -> 37.666667 | Y13: ='HOJA RXH'!AD9 -> 171 | Z13: =(T13/30/8/60*Y13) -> 20.54375 | AH13: ='HOJA RXH'!V9 -> 0 | AJ13: =(((P13+Q13)/30)*U13)-Z13+AA13+AB13+AC13+AF13+AG13+AI13 -> 506.78958 | AK13: ='HOJA RXH'!J9 -> 0 | AL13: =T13/30*AK13 -> 0 | AM13: ='HOJA RXH'!F9 -> 0 | AN13: =T13/30/10*AM13 -> 0 | AO13: ='HOJA RXH'!N9 -> 0 | AP13: =T13/30*AO13 -> 0 | AQ13: 0 | AR13: =((R13/$C$3)*(U13-V13))+AL13+AP13+AN13+AQ13 -> 280 | AS13: PRIMA FLUJO | AT13: 0.016 | AU13: 0.0137 | AV13: =IF(AS13="ONP",VLOOKUP(AS13,TASAS!TAB_AFP,8,0)*AJ13,0) -> 0 | AW13: =IF(AS13<>"ONP",AJ13*$AW$8,0) -> 50.678958 | AX13: =IF(AS13<>"ONP",AJ13*AT13,0) -> 8.1086333 | AY13: =IF(AU13<>"ONP",AJ13*AU13,0) -> 6.9430173 | AZ13: =+AX13+AY13+AW13 -> 65.730609 | BA13: =+AZ13+AV13 -> 65.730609 | BC13: =AJ13+AR13-BA13-BB13 -> 721.05897 | BD13: =ROUND(AJ13*$BD$8,2) -> 45.61 | BE13: 44.99 | BG13: =+P13*0.54% -> 6.102 | BJ13: =BC13-BH13+BI13 -> 721.05897
A14: 5 | B14: GAVIDIA PEREIRA JAVIER | C14: 13/03/1969 | D14: 7717984 | E14: 46143 | G14: MASCULINO | H14: A PLAZO FIJO | I14: EMPLEADO | J14: NO | K14: SI | L14: NO | N14: ADMINISTRACIÓN | O14: ADMINISTRADOR GENERAL | P14: 6000 | T14: =P14+Q14+R14+S14 -> 6000 | U14: ='HOJA RXH'!AH10 -> 15 | W14: ='HOJA RXH'!Z10 -> 0 | X14: =((P14+Q14)/$C$3)*W14 -> 0 | Y14: ='HOJA RXH'!AD10 -> 0 | Z14: =(T14/30/8/60*Y14) -> 0 | AH14: ='HOJA RXH'!V10 -> 0 | AJ14: =(((P14+Q14)/30)*U14)-Z14+AA14+AB14+AC14+AF14+AG14+AI14 -> 3000 | AK14: ='HOJA RXH'!J10 -> 0 | AL14: =T14/30*AK14 -> 0 | AM14: ='HOJA RXH'!F10 -> 0 | AN14: =T14/30/10*AM14 -> 0 | AO14: ='HOJA RXH'!N10 -> 0 | AP14: =T14/30*AO14 -> 0 | AQ14: 0 | AR14: =((R14/$C$3)*(U14-V14))+AL14+AP14+AN14+AQ14 -> 0 | AS14: 0 | AV14: =IF(AS14="ONP",VLOOKUP(AS14,TASAS!TAB_AFP,8,0)*AJ14,0) -> 0 | AW14: 0 | AX14: =IF(AS14<>"ONP",AJ14*AT14,0) -> 0 | AY14: =IF(AU14<>"ONP",AJ14*AU14,0) -> 0 | AZ14: =+AX14+AY14+AW14 -> 0 | BA14: =+AZ14+AV14 -> 0 | BC14: =AJ14+AR14-BA14-BB14 -> 3000 | BD14: =ROUND(AJ14*$BD$8,2) -> 270 | BE14: =IF(K14="SI",AJ14*2.14%,0) -> 64.2 | BG14: =+P14*0.54% -> 32.4 | BJ14: =BC14-BH14+BI14 -> 3000
A15: 6 | B15: HIDALGO MOYA, LIZBETH SONIA | C15: 30319 | D15: 41705366 | E15: 40210 | G15: FEMENINO | H15: INDETERMINADO | I15: EMPLEADO | J15: SI | K15: NO | L15: NO | M15: 603170LHMAA7 | N15: LOGISTICA | O15: JEFA DE LOGISTICA | P15: =2000+1000 -> 3000 | Q15: 113 | R15: 1000 | T15: =P15+Q15+R15+S15 -> 4113 | U15: ='HOJA RXH'!AH11 -> 15 | W15: ='HOJA RXH'!Z11 -> 0 | X15: =((P15+Q15)/$C$3)*W15 -> 0 | Y15: ='HOJA RXH'!AD11 -> 0 | Z15: =(T15/30/8/60*Y15) -> 0 | AH15: ='HOJA RXH'!V11 -> 0 | AJ15: =(((P15+Q15)/30)*U15)-Z15+AA15+AB15+AC15+AF15+AG15+AI15 -> 1556.5 | AK15: ='HOJA RXH'!J11 -> 0 | AL15: =T15/30*AK15 -> 0 | AM15: ='HOJA RXH'!F11 -> 0 | AN15: =T15/30/10*AM15 -> 0 | AO15: ='HOJA RXH'!N11 -> 0 | AP15: =T15/30*AO15 -> 0 | AQ15: 0 | AR15: =((R15/$C$3)*(U15-V15))+AL15+AP15+AN15+AQ15 -> 500 | AS15: PROFUTURO MIXTA | AT15: 0 | AU15: 0.0137 | AV15: =IF(AS15="ONP",VLOOKUP(AS15,TASAS!TAB_AFP,8,0)*AJ15,0) -> 0 | AW15: =IF(AS15<>"ONP",AJ15*$AW$8,0) -> 155.65 | AX15: =IF(AS15<>"ONP",AJ15*AT15,0) -> 0 | AY15: =IF(AU15<>"ONP",AJ15*AU15,0) -> 21.32405 | AZ15: =+AX15+AY15+AW15 -> 176.97405 | BA15: =+AZ15+AV15 -> 176.97405 | BC15: =AJ15+AR15-BA15-BB15 -> 1879.5259 | BD15: =ROUND(AJ15*$BD$8,2) -> 140.09 | BE15: =IF(K15="SI",AJ15*2.14%,0) -> 0 | BG15: =+P15*0.54% -> 16.2 | BJ15: =BC15-BH15+BI15 -> 1879.5259
A16: 7 | B16: LAGOS HUAMANI NIDIA | C16: 35114 | D16: 76339850 | E16: 45152 | G16: FEMENINO | H16: MYPE CONTRAT | I16: EMPLEADO | J16: NO | K16: NO | L16: NO | M16: 651120NLHOM8 | N16: CONTABILIDAD | O16: AUXILIAR | P16: 1200 | R16: =300+300 -> 600 | T16: =P16+Q16+R16+S16 -> 1800 | U16: ='HOJA RXH'!AH12 -> 15 | W16: ='HOJA RXH'!Z12 -> 0 | X16: =((P16+Q16)/$C$3)*W16 -> 0 | Y16: ='HOJA RXH'!AD12 -> 839 | Z16: =(T16/30/8/60*Y16) -> 104.875 | AH16: ='HOJA RXH'!V12 -> 0 | AJ16: =(((P16+Q16)/30)*U16)-Z16+AA16+AB16+AC16+AF16+AG16+AI16 -> 495.125 | AK16: ='HOJA RXH'!J12 -> 0 | AL16: =T16/30*AK16 -> 0 | AM16: ='HOJA RXH'!F12 -> 0 | AN16: =T16/30/10*AM16 -> 0 | AO16: ='HOJA RXH'!N12 -> 0 | AP16: =T16/30*AO16 -> 0 | AQ16: 0 | AR16: =((R16/$C$3)*(U16-V16))+AL16+AP16+AN16+AQ16 -> 300 | AS16: INTEGRA MIXTA | AT16: 0 | AU16: 0.0137 | AV16: =IF(AS16="ONP",VLOOKUP(AS16,TASAS!TAB_AFP,8,0)*AJ16,0) -> 0 | AW16: =IF(AS16<>"ONP",AJ16*$AW$8,0) -> 49.5125 | AX16: =IF(AS16<>"ONP",AJ16*AT16,0) -> 0 | AY16: =IF(AU16<>"ONP",AJ16*AU16,0) -> 6.7832125 | AZ16: =+AX16+AY16+AW16 -> 56.295712 | BA16: =+AZ16+AV16 -> 56.295712 | BC16: =AJ16+AR16-BA16-BB16 -> 738.82929 | BD16: =ROUND(AJ16*$BD$8,2) -> 44.56 | BE16: =IF(K16="SI",AJ16*2.14%,0) -> 0 | BG16: =+P16*0.54% -> 6.48 | BJ16: =BC16-BH16+BI16 -> 738.82929
A17: 8 | B17: MERCADO SANCHEZ NORMA AURELIA | C17: 29693 | D17: 40878166 | E17: 38534 | G17: FEMENINO | H17: INDETERMINADO | I17: EMPLEADO | J17: NO | K17: NO | L17: NO | M17: 596910NMSCC9 | N17: VENTAS | O17: ASISTENTE DE VENTAS | P17: =1425+175+300 -> 1900 | Q17: 113 | T17: =P17+Q17+R17+S17 -> 2013 | U17: ='HOJA RXH'!AH13 -> 15 | W17: ='HOJA RXH'!Z13 -> 0 | X17: =((P17+Q17)/$C$3)*W17 -> 0 | Y17: ='HOJA RXH'!AD13 -> 663 | Z17: =(T17/30/8/60*Y17) -> 92.681875 | AH17: ='HOJA RXH'!V13 -> 0 | AJ17: =(((P17+Q17)/30)*U17)-Z17+AA17+AB17+AC17+AF17+AG17+AI17 -> 913.81812 | AK17: ='HOJA RXH'!J13 -> 0 | AL17: =T17/30*AK17 -> 0 | AM17: ='HOJA RXH'!F13 -> 1 | AN17: =T17/30/10*AM17 -> 6.71 | AO17: ='HOJA RXH'!N13 -> 0 | AP17: =T17/30*AO17 -> 0 | AQ17: 0 | AR17: =((R17/$C$3)*(U17-V17))+AL17+AP17+AN17+AQ17 -> 6.71 | AS17: PROFUTURO MIXTA | AT17: 0 | AU17: 0.0137 | AV17: =IF(AS17="ONP",VLOOKUP(AS17,TASAS!TAB_AFP,8,0)*AJ17,0) -> 0 | AW17: =IF(AS17<>"ONP",AJ17*$AW$8,0) -> 91.381812 | AX17: =IF(AS17<>"ONP",AJ17*AT17,0) -> 0 | AY17: =IF(AU17<>"ONP",AJ17*AU17,0) -> 12.519308 | AZ17: =+AX17+AY17+AW17 -> 103.90112 | BA17: =+AZ17+AV17 -> 103.90112 | BC17: =AJ17+AR17-BA17-BB17 -> 816.627 | BD17: =ROUND(AJ17*$BD$8,2) -> 82.24 | BE17: =IF(K17="SI",AJ17*2.14%,0) -> 0 | BG17: =+P17*0.54% -> 10.26 | BJ17: =BC17-BH17+BI17 -> 816.627
A18: 9 | B18: MONTENEGRO OBLITAS GROVER MANUEL | C18: 30536 | D18: 41974116 | E18: 43862 | G18: MASCULINO | H18: INDETERMINADO | I18: OBRERO | J18: SI | K18: SI | L18: NO | N18: CORTE DOBLEZ | O18: DOBLADOR | P18: 1130 | Q18: 113 | R18: =600+200+200 -> 1000 | T18: =P18+Q18+R18+S18 -> 2243 | U18: ='HOJA RXH'!AH14 -> 15 | W18: ='HOJA RXH'!Z14 -> 0 | X18: =((P18+Q18)/$C$3)*W18 -> 0 | Y18: ='HOJA RXH'!AD14 -> 22 | Z18: =(T18/30/8/60*Y18) -> 3.4268056 | AH18: ='HOJA RXH'!V14 -> 0 | AJ18: =(((P18+Q18)/30)*U18)-Z18+AA18+AB18+AC18+AF18+AG18+AI18 -> 618.07319 | AK18: ='HOJA RXH'!J14 -> 2 | AL18: =T18/30*AK18 -> 149.53333 | AM18: ='HOJA RXH'!F14 -> 10 | AN18: =T18/30/10*AM18 -> 74.766667 | AO18: ='HOJA RXH'!N14 -> 0 | AP18: =T18/30*AO18 -> 0 | AQ18: 0 | AR18: =((R18/$C$3)*(U18-V18))+AL18+AP18+AN18+AQ18 -> 724.3 | AS18: ONP | AV18: =IF(AS18="ONP",VLOOKUP(AS18,TASAS!TAB_AFP,8,0)*AJ18,0) -> 80.349515 | AW18: =IF(AS18<>"ONP",AJ18*$AW$8,0) -> 0 | AX18: =IF(AS18<>"ONP",AJ18*AT18,0) -> 0 | AY18: =IF(AU18<>"ONP",AJ18*AU18,0) -> 0 | AZ18: =+AX18+AY18+AW18 -> 0 | BA18: =+AZ18+AV18 -> 80.349515 | BC18: =AJ18+AR18-BA18-BB18 -> 1262.0237 | BD18: =ROUND(AJ18*$BD$8,2) -> 55.63 | BE18: =IF(K18="SI",AJ18*2.14%,0) -> 13.226766 | BG18: =+P18*0.54% -> 6.102 | BH18: 150 | BJ18: =BC18-BH18+BI18 -> 1112.0237 | BK18: 450 PRESTAMO/ADELANTO DE SUELDO
A19: 10 | B19: PEÑALOZA CAMPOS, FRANK KEVHIN | C19: 30680 | D19: 42137816 | E19: 40210 | G19: MASCULINO | H19: INDETERMINADO | I19: OBRERO | J19: NO | K19: SI | L19: NO | M19: 606781FPCAP2 | N19: ESTRUCTURA | O19: ARMADOR | P19: 1500 | Q19: 113 | R19: 1500 | T19: =P19+Q19+R19+S19 -> 3113 | U19: ='HOJA RXH'!AH15 -> 15 | W19: ='HOJA RXH'!Z15 -> 0 | X19: =((P19+Q19)/$C$3)*W19 -> 0 | Y19: ='HOJA RXH'!AD15 -> 0 | Z19: =(T19/30/8/60*Y19) -> 0 | AH19: ='HOJA RXH'!V15 -> 0 | AJ19: =(((P19+Q19)/30)*U19)-Z19+AA19+AB19+AC19+AF19+AG19+AI19 -> 806.5 | AK19: ='HOJA RXH'!J15 -> 2 | AL19: =T19/30*AK19 -> 207.53333 | AM19: ='HOJA RXH'!F15 -> 3 | AN19: =T19/30/10*AM19 -> 31.13 | AO19: ='HOJA RXH'!N15 -> 0 | AP19: =T19/30*AO19 -> 0 | AQ19: 0 | AR19: =((R19/$C$3)*(U19-V19))+AL19+AP19+AN19+AQ19 -> 988.66333 | AS19: PROFUTURO FLUJO | AT19: 0.0169 | AU19: 0.0137 | AV19: =IF(AS19="ONP",VLOOKUP(AS19,TASAS!TAB_AFP,8,0)*AJ19,0) -> 0 | AW19: =IF(AS19<>"ONP",AJ19*$AW$8,0) -> 80.65 | AX19: =IF(AS19<>"ONP",AJ19*AT19,0) -> 13.62985 | AY19: =IF(AU19<>"ONP",AJ19*AU19,0) -> 11.04905 | AZ19: =+AX19+AY19+AW19 -> 105.3289 | BA19: =+AZ19+AV19 -> 105.3289 | BC19: =AJ19+AR19-BA19-BB19 -> 1689.8344 | BD19: =ROUND(AJ19*$BD$8,2) -> 72.59 | BE19: =IF(K19="SI",AJ19*2.14%,0) -> 17.2591 | BG19: =+P19*0.54% -> 8.1 | BJ19: =BC19-BH19+BI19 -> 1689.8344
A20: 11 | B20: SANCHEZ MUEDAS FIDEL | C20: 25284 | D20: 19898777 | E20: 40788 | G20: MASCULINO | H20: INDETERMINADO | I20: EMPLEADO | J20: NO | K20: SI | L20: NO | M20: 252821FSMCD6 | N20: ALMACEN | O20: ALMACENERO | P20: 1200 | Q20: 0 | R20: 300 | T20: =P20+Q20+R20+S20 -> 1500 | U20: ='HOJA RXH'!AH16 -> 15 | W20: ='HOJA RXH'!Z16 -> 0 | X20: =((P20+Q20)/$C$3)*W20 -> 0 | Y20: ='HOJA RXH'!AD16 -> 55 | Z20: =(T20/30/8/60*Y20) -> 5.7291667 | AH20: ='HOJA RXH'!V16 -> 0 | AJ20: =(((P20+Q20)/30)*U20)-Z20+AA20+AB20+AC20+AF20+AG20+AI20 -> 594.27083 | AK20: ='HOJA RXH'!J16 -> 0 | AL20: =T20/30*AK20 -> 0 | AM20: ='HOJA RXH'!F16 -> 1 | AN20: =T20/30/10*AM20 -> 5 | AO20: ='HOJA RXH'!N16 -> 0 | AP20: =T20/30*AO20 -> 0 | AQ20: 0 | AR20: =((R20/$C$3)*(U20-V20))+AL20+AP20+AN20+AQ20 -> 155 | AS20: INTEGRA FLUJO | AT20: 0.0155 | AU20: 0.0137 | AV20: =IF(AS20="ONP",VLOOKUP(AS20,TASAS!TAB_AFP,8,0)*AJ20,0) -> 0 | AW20: =IF(AS20<>"ONP",AJ20*$AW$8,0) -> 59.427083 | AX20: =IF(AS20<>"ONP",AJ20*AT20,0) -> 9.2111979 | AY20: =IF(AU20<>"ONP",AJ20*AU20,0) -> 8.1415104 | AZ20: =+AX20+AY20+AW20 -> 76.779792 | BA20: =+AZ20+AV20 -> 76.779792 | BC20: =AJ20+AR20-BA20-BB20 -> 672.49104 | BD20: =ROUND(AJ20*$BD$8,2) -> 53.48 | BE20: =IF(K20="SI",AJ20*2.14%,0) -> 12.717396 | BG20: =+P20*0.54% -> 6.48 | BJ20: =BC20-BH20+BI20 -> 672.49104
A21: 12 | B21: SEVERICHE CARLOS ANGELICA JESUS | C21: 29010 | D21: 40247925 | E21: 41918 | G21: FEMENINO | H21: INDETERMINADO | I21: EMPLEADO | J21: SI | K21: NO | L21: NO | N21: CONTABILIDAD | O21: CONTADORA | P21: 4000 | Q21: 113 | R21: 0 | T21: =P21+Q21+R21+S21 -> 4113 | U21: ='HOJA RXH'!AH17 -> 15 | W21: ='HOJA RXH'!Z17 -> 0 | X21: =((P21+Q21)/$C$3)*W21 -> 0 | Y21: ='HOJA RXH'!AD17 -> 0 | Z21: =(T21/30/8/60*Y21) -> 0 | AH21: ='HOJA RXH'!V17 -> 0 | AJ21: =(((P21+Q21)/30)*U21)-Z21+AA21+AB21+AC21+AF21+AG21+AI21 -> 2056.5 | AK21: ='HOJA RXH'!J17 -> 0 | AL21: =T21/30*AK21 -> 0 | AM21: ='HOJA RXH'!F17 -> 0 | AN21: =T21/30/10*AM21 -> 0 | AO21: ='HOJA RXH'!N17 -> 0 | AP21: =T21/30*AO21 -> 0 | AQ21: 0 | AR21: =((R21/$C$3)*(U21-V21))+AL21+AP21+AN21+AQ21 -> 0 | AS21: ONP | AV21: =IF(AS21="ONP",VLOOKUP(AS21,TASAS!TAB_AFP,8,0)*AJ21,0) -> 267.345 | AW21: =IF(AS21<>"ONP",AJ21*$AW$8,0) -> 0 | AX21: =IF(AS21<>"ONP",AJ21*AT21,0) -> 0 | AY21: =IF(AU21<>"ONP",AJ21*AU21,0) -> 0 | AZ21: =+AX21+AY21+AW21 -> 0 | BA21: =+AZ21+AV21 -> 267.345 | BC21: =AJ21+AR21-BA21-BB21 -> 1789.155 | BD21: =ROUND(AJ21*$BD$8,2) -> 185.09 | BE21: =IF(K21="SI",AJ21*2.14%,0) -> 0 | BG21: =+P21*0.54% -> 21.6 | BJ21: =BC21-BH21+BI21 -> 1789.155
A22: 13 | B22: TENORIO MARTINEZ DE CISNEROS RUTH LOURDES | C22: 28961 | D22: 40986687 | E22: 44028 | G22: FEMENINO | H22: MYPE CONTRAT | I22: EMPLEADO | J22: NO | K22: NO | L22: NO | M22: 589590RTMOT3 | N22: ADMINISTRACION | O22: ASIST ADMINIST | P22: =3000+2000 -> 5000 | Q22: 113 | R22: 1000 | T22: =P22+Q22+R22+S22 -> 6113 | U22: ='HOJA RXH'!AH18 -> 15 | W22: ='HOJA RXH'!Z18 -> 0 | X22: =((P22+Q22)/$C$3)*W22 -> 0 | Y22: ='HOJA RXH'!AD18 -> 0 | Z22: =(T22/30/8/60*Y22) -> 0 | AH22: ='HOJA RXH'!V18 -> 0 | AJ22: =(((P22+Q22)/30)*U22)-Z22+AA22+AB22+AC22+AF22+AG22+AI22 -> 2556.5 | AK22: ='HOJA RXH'!J18 -> 0 | AL22: =T22/30*AK22 -> 0 | AM22: ='HOJA RXH'!F18 -> 0 | AN22: =T22/30/10*AM22 -> 0 | AO22: ='HOJA RXH'!N18 -> 0 | AP22: =T22/30*AO22 -> 0 | AQ22: 0 | AR22: =((R22/$C$3)*(U22-V22))+AL22+AP22+AN22+AQ22 -> 500 | AS22: INTEGRA MIXTA | AT22: 0 | AU22: 0.0137 | AV22: =IF(AS22="ONP",VLOOKUP(AS22,TASAS!TAB_AFP,8,0)*AJ22,0) -> 0 | AW22: =IF(AS22<>"ONP",AJ22*$AW$8,0) -> 255.65 | AX22: =IF(AS22<>"ONP",AJ22*AT22,0) -> 0 | AY22: =IF(AU22<>"ONP",AJ22*AU22,0) -> 35.02405 | AZ22: =+AX22+AY22+AW22 -> 290.67405 | BA22: =+AZ22+AV22 -> 290.67405 | BC22: =AJ22+AR22-BA22-BB22 -> 2765.8259 | BD22: =ROUND(AJ22*$BD$8,2) -> 230.09 | BE22: =IF(K22="SI",AJ22*2.14%,0) -> 0 | BG22: =+P22*0.54% -> 27 | BJ22: =BC22-BH22+BI22 -> 2765.8259
A23: 14 | B23: VASQUEZ CUNYAS, JOSE EDGAR | C23: 33135 | D23: 46586240 | E23: 45673 | G23: MASCULINO | H23: MYPE CONTRAT | I23: OBRERO | J23: NO | K23: SI | L23: NO | M23: 631331JVCQY3 | N23: PINTURA | O23: PINTOR | P23: 3000 | T23: =P23+Q23+R23+S23 -> 3000 | U23: ='HOJA RXH'!AH19 -> 15 | W23: ='HOJA RXH'!Z19 -> 0 | X23: =((P23+Q23)/$C$3)*W23 -> 0 | Y23: ='HOJA RXH'!AD19 -> 0 | Z23: =(T23/30/8/60*Y23) -> 0 | AG23: 300 | AH23: ='HOJA RXH'!V19 -> 0 | AJ23: =(((P23+Q23)/30)*U23)-Z23+AA23+AB23+AC23+AF23+AG23+AI23 -> 1800 | AK23: ='HOJA RXH'!J19 -> 2 | AL23: =T23/30*AK23 -> 200 | AM23: ='HOJA RXH'!F19 -> 3 | AN23: =T23/30/10*AM23 -> 30 | AO23: ='HOJA RXH'!N19 -> 0 | AP23: =T23/30*AO23 -> 0 | AQ23: 0 | AR23: =((R23/$C$3)*(U23-V23))+AL23+AP23+AN23+AQ23 -> 230 | AS23: INTEGRA MIXTA | AT23: 0 | AU23: 0.0137 | AV23: =IF(AS23="ONP",VLOOKUP(AS23,TASAS!TAB_AFP,8,0)*AJ23,0) -> 0 | AW23: =IF(AS23<>"ONP",AJ23*$AW$8,0) -> 180 | AX23: =IF(AS23<>"ONP",AJ23*AT23,0) -> 0 | AY23: =IF(AU23<>"ONP",AJ23*AU23,0) -> 24.66 | AZ23: =+AX23+AY23+AW23 -> 204.66 | BA23: =+AZ23+AV23 -> 204.66 | BC23: =AJ23+AR23-BA23-BB23 -> 1825.34 | BD23: =ROUND(AJ23*$BD$8,2) -> 162 | BE23: =IF(K23="SI",AJ23*2.14%,0) -> 38.52 | BG23: =+P23*0.54% -> 16.2 | BJ23: =BC23-BH23+BI23 -> 1825.34
A24: 15 | B24: ZACARIAS CORONEL MIGUEL ANGEL | C24: 17/03/1998 | D24: 74171661 | E24: 44835 | G24: MASCULINO | H24: MYPE CONTRAT | I24: OBRERO | J24: NO | K24: SI | L24: NO | M24: 658691MZCAO5 | N24: ESTRUCTURA | O24: ARMADOR | P24: 1600 | R24: =135+65+300 -> 500 | T24: =P24+Q24+R24+S24 -> 2100 | U24: ='HOJA RXH'!AH20 -> 13 | W24: ='HOJA RXH'!Z20 -> 2 | X24: =((P24+Q24)/$C$3)*W24 -> 106.66667 | Y24: ='HOJA RXH'!AD20 -> 60 | Z24: =(T24/30/8/60*Y24) -> 8.75 | AH24: ='HOJA RXH'!V20 -> 0 | AJ24: =(((P24+Q24)/30)*U24)-Z24+AA24+AB24+AC24+AF24+AG24+AI24 -> 684.58333 | AK24: ='HOJA RXH'!J20 -> 1 | AL24: =T24/30*AK24 -> 70 | AM24: ='HOJA RXH'!F20 -> 2 | AN24: =T24/30/10*AM24 -> 14 | AO24: ='HOJA RXH'!N20 -> 0 | AP24: =T24/30*AO24 -> 0 | AQ24: 0 | AR24: =((R24/$C$3)*(U24-V24))+AL24+AP24+AN24+AQ24 -> 300.66667 | AS24: PRIMA | AT24: 0 | AU24: 0.0137 | AV24: =IF(AS24="ONP",VLOOKUP(AS24,TASAS!TAB_AFP,8,0)*AJ24,0) -> 0 | AW24: =IF(AS24<>"ONP",AJ24*$AW$8,0) -> 68.458333 | AX24: =IF(AS24<>"ONP",AJ24*AT24,0) -> 0 | AY24: =IF(AU24<>"ONP",AJ24*AU24,0) -> 9.3787917 | AZ24: =+AX24+AY24+AW24 -> 77.837125 | BA24: =+AZ24+AV24 -> 77.837125 | BC24: =AJ24+AR24-BA24-BB24 -> 907.41287 | BD24: =ROUND(AJ24*$BD$8,2) -> 61.61 | BE24: =IF(K24="SI",AJ24*2.14%,0) -> 14.650083 | BG24: =+P24*0.54% -> 8.64 | BJ24: =BC24-BH24+BI24 -> 907.41287
P25: =SUM(P10:P24) -> 41690 | Q25: =SUM(Q10:Q24) -> 904 | R25: =SUM(R10:R24) -> 8250 | S25: =SUM(S10:S24) -> 0 | T25: =SUM(T10:T24) -> 50844 | U25: =SUM(U10:U24) -> 215 | V25: =SUM(V10:V24) -> 0 | W25: =SUM(W10:W24) -> 10 | ... AR25: =SUM(AR10:AR24) -> 5276.2067 | AT25: =SUM(AT10:AT24) -> 0.0653 | AU25: =SUM(AU10:AU24) -> 0.1644 | AV25: =SUM(AV10:AV24) -> 347.69452 | AW25: =SUM(AW10:AW24) -> 1447.7949 | AX25: =SUM(AX10:AX24) -> 65.704531 | AY25: =SUM(AY10:AY24) -> 198.34791 | AZ25: =SUM(AZ10:AZ24) -> 1711.8474 | BA25: =SUM(BA10:BA24) -> 2059.5419 | ... BJ25: =SUM(BJ10:BJ24) -> 23219.187

Sheet ASISTENCIA
D1: REFRIGERIO | M1: LEYENDA
A2: TURNO | B2: HR. ENTRADA | C2: HR. SALIDA | D2: HR. SALIDA (REFR.) | E2: HR. REGRESO (REFR,) | F2: TOTAL DE REFRIGERIO | G2: HRS. ESPERADAS | H2: MIN. ESPERADOS | M2: ESCRIBIR EN LA COLUMNA ASISTENCIA DIARIA | O2: COLUMNA SOLICITUD DEL SUPERVISOR
A3: 1 | B3: 0.30763889 | C3: 0.75 | D3: 0.5 | E3: 0.54166667 | F3: =E3-D3 -> 0.041666667 | G3: =C3-B3-F3 -> 0.40069444 | H3: =G3*1440 -> 577 | M3: DIA NORMAL | O3: NO
A4: 2 | B4: 0.33333333 | C4: 0.75 | D4: 0.5 | E4: 0.54166667 | F4: =E4-D4 -> 0.041666667 | G4: =C4-B4-F4 -> 0.375 | H4: =G4*1440 -> 540 | M4: SI ESTÁ DE VACACIONES | N4: VACACIONES | O4: SI
M5: SI FALTÓ | N5: FALTA
M6: SI ESTÁ DE LICENCIA | N6: LICENCIA
A7: CONSIDERACIONES | M7: SI JUSTFICÓ | N7: JUSTIFICADO
A8: 1 | B8: SOLO CAMBIAR LAS CELDAS DE HR. ENTRADA - SALIDA Y LA COLUMNA DE ASISTENCIA DIARIA. | M8: SI TRABAJÓ UN SABADO | N8: TRABAJO SABADO
M9: SI TRABAJÓ UN DOMINGO | N9: TRABAJO DOMINGO
A10: 2 | B10: SOLO CAMBIAR LA PRIMERA FECHA, LOS DIAS SIGUIENTES DE AMBAS QUINCENAS SE ACTUALIZAN AUTOMATICAMENTE. | M10: SI TRABAJÓ UN FERIADO | N10: TRABAJO FERIADO
M11: SI TRABAJÓ EL 1RO DE MAYO | N11: TRABAJO 1RO MAYO
M12: SI TRABAJÓ EL 1RO DE MAYO EN SU DIA LIBRE | N12: TRABAJO 1RO MAYO EN SU DIA LIBRE
D15: =IF(AND(DAY(D17)=1,MONTH(D17)=5),"⚠️ HOY ES 1 DE MAYO - PAGO DOBLE","") | M15: =IF(AND(DAY(M17)=1,MONTH(M17)=5),"⚠️ HOY ES 1 DE MAYO - PAGO DOBLE","") | V15: =IF(AND(DAY(V17)=1,MONTH(V17)=5),"⚠️ HOY ES 1 DE MAYO - PAGO DOBLE","") | AE15: =IF(AND(DAY(AE17)=1,MONTH(AE17)=5),"⚠️ HOY ES 1 DE MAYO - PAGO DOBLE","") | AN15: =IF(AND(DAY(AN17)=1,MONTH(AN17)=5),"⚠️ HOY ES 1 DE MAYO - PAGO DOBLE","") | AW15: =IF(AND(DAY(AW17)=1,MONTH(AW17)=5),"⚠️ HOY ES 1 DE MAYO - PAGO DOBLE","") | BF15: =IF(AND(DAY(BF17)=1,MONTH(BF17)=5),"⚠️ HOY ES 1 DE MAYO - PAGO DOBLE","") | BO15: =IF(AND(DAY(BO17)=1,MONTH(BO17)=5),"⚠️ HOY ES 1 DE MAYO - PAGO DOBLE","") | BX15: =IF(AND(DAY(BX17)=1,MONTH(BX17)=5),"⚠️ HOY ES 1 DE MAYO - PAGO DOBLE","") | CG15: =IF(AND(DAY(CG17)=1,MONTH(CG17)=5),"⚠️ HOY ES 1 DE MAYO - PAGO DOBLE","") | CP15: =IF(AND(DAY(CP17)=1,MONTH(CP17)=5),"⚠️ HOY ES 1 DE MAYO - PAGO DOBLE","") | CY15: =IF(AND(DAY(CY17)=1,MONTH(CY17)=5),"⚠️ HOY ES 1 DE MAYO - PAGO DOBLE","") | DH15: =IF(AND(DAY(DH17)=1,MONTH(DH17)=5),"⚠️ HOY ES 1 DE MAYO - PAGO DOBLE","") | DQ15: =IF(AND(DAY(DQ17)=1,MONTH(DQ17)=5),"⚠️ HOY ES 1 DE MAYO - PAGO DOBLE","") | DZ15: =IF(AND(DAY(DZ17)=1,MONTH(DZ17)=5),"⚠️ HOY ES 1 DE MAYO - PAGO DOBLE","") | EK15: CUADRO RESUMEN PRIMERA QUINCENA
A16: DATOS | D16: =UPPER(TEXT(D17,"DDDD")) -> LUNES | M16: =UPPER(TEXT(M17,"DDDD")) -> MARTES | V16: =UPPER(TEXT(V17,"DDDD")) -> MIÉRCOLES | AE16: =UPPER(TEXT(AE17,"DDDD")) -> JUEVES | AN16: =UPPER(TEXT(AN17,"DDDD")) -> VIERNES | AW16: =UPPER(TEXT(AW17,"DDDD")) -> SÁBADO | BF16: =UPPER(TEXT(BF17,"DDDD")) -> DOMINGO | BO16: =UPPER(TEXT(BO17,"DDDD")) -> LUNES | BX16: =UPPER(TEXT(BX17,"DDDD")) -> MARTES | CG16: =UPPER(TEXT(CG17,"DDDD")) -> MIÉRCOLES | CP16: =UPPER(TEXT(CP17,"DDDD")) -> JUEVES | CY16: =UPPER(TEXT(CY17,"DDDD")) -> VIERNES | DH16: =UPPER(TEXT(DH17,"DDDD")) -> SÁBADO | DQ16: =UPPER(TEXT(DQ17,"DDDD")) -> DOMINGO | DZ16: =UPPER(TEXT(DZ17,"DDDD")) -> LUNES | EK16: TARDANZA (MIN.) | EL16: CANT. HRS. EXTRA (MIN.) | EM16: CANT. HRS. EXTRA (DIAS) | EN16: FALTAS | EO16: DIAS TRABAJADOS | EP16: SABADO | EQ16: FERIADOS Y DOMINGOS | ER16: VACACIONES | ES16: LICENCIA HIJO ENFERMO
D17: 46174 | M17: =D17+1 -> 46175 | V17: =M17+1 -> 46176 | AE17: =V17+1 -> 46177 | AN17: =AE17+1 -> 46178 | AW17: =AN17+1 -> 46179 | BF17: =AW17+1 -> 46180 | BO17: =BF17+1 -> 46181 | BX17: =BO17+1 -> 46182 | CG17: =BX17+1 -> 46183 | CP17: =CG17+1 -> 46184 | CY17: =CP17+1 -> 46185 | DH17: =CY17+1 -> 46186 | DQ17: =DH17+1 -> 46187 | DZ17: =DQ17+1 -> 46188
A18: N° | B18: APELLIDO, NOMBRE | C18: TURNO | D18: HR. ENTRADA | E18: HR. SALIDA | F18: SOLICITUD DEL SUPERVISOR | G18: HRS. LAB. | H18: TARDANZA (MIN.) | I18: L - V (MIN. EXTRA) | J18: SAB. - DOM. EXTRA (MIN.) | K18: ASISTENCIA DIARIA | M18: HR. ENTRADA | N18: HR. SALIDA | O18: SOLICITUD DEL SUPERVISOR | P18: HRS. LAB. | Q18: TARDANZA (MIN.) | R18: L - V (MIN. EXTRA) | S18: SAB. - DOM. EXTRA (MIN.) | T18: ASISTENCIA DIARIA | V18: HR. ENTRADA | W18: HR. SALIDA | X18: SOLICITUD DEL SUPERVISOR | Y18: HRS. LAB. | Z18: TARDANZA (MIN.) | AA18: L - V (MIN. EXTRA) | AB18: SAB. - DOM. EXTRA (MIN.) | AC18: ASISTENCIA DIARIA | AE18: HR. ENTRADA | AF18: HR. SALIDA | AG18: SOLICITUD DEL SUPERVISOR | AH18: HRS. LAB. | AI18: TARDANZA (MIN.) | AJ18: L - V (MIN. EXTRA) | AK18: SAB. - DOM. EXTRA (MIN.) | AL18: ASISTENCIA DIARIA | AN18: HR. ENTRADA | AO18: HR. SALIDA | AP18: SOLICITUD DEL SUPERVISOR | AQ18: HRS. LAB. | AR18: TARDANZA (MIN.) | AS18: L - V (MIN. EXTRA) | AT18: SAB. - DOM. EXTRA (MIN.) | AU18: ASISTENCIA DIARIA | AW18: HR. ENTRADA | AX18: HR. SALIDA | AY18: SOLICITUD DEL SUPERVISOR | AZ18: HRS. LAB. | BA18: TARDANZA (MIN.) | BB18: L - V (MIN. EXTRA) | BC18: SAB. - DOM. EXTRA (MIN.) | BD18: ASISTENCIA DIARIA | BF18: HR. ENTRADA | BG18: HR. SALIDA | BH18: SOLICITUD DEL SUPERVISOR | BI18: HRS. LAB. | BJ18: TARDANZA (MIN.) | BK18: L - V (MIN. EXTRA) | BL18: SAB. - DOM. EXTRA (MIN.) | BM18: ASISTENCIA DIARIA | BO18: HR. ENTRADA | BP18: HR. SALIDA | BQ18: SOLICITUD DEL SUPERVISOR | BR18: HRS. LAB. | BS18: TARDANZA (MIN.) | BT18: L - V (MIN. EXTRA) | BU18: SAB. - DOM. EXTRA (MIN.) | BV18: ASISTENCIA DIARIA | BX18: HR. ENTRADA | BY18: HR. SALIDA | BZ18: SOLICITUD DEL SUPERVISOR | CA18: HRS. LAB. | CB18: TARDANZA (MIN.) | CC18: L - V (MIN. EXTRA) | CD18: SAB. - DOM. EXTRA (MIN.) | CE18: ASISTENCIA DIARIA | CG18: HR. ENTRADA | CH18: HR. SALIDA | CI18: SOLICITUD DEL SUPERVISOR | CJ18: HRS. LAB. | CK18: TARDANZA (MIN.) | CL18: L - V (MIN. EXTRA) | CM18: SAB. - DOM. EXTRA (MIN.) | CN18: ASISTENCIA DIARIA | CP18: HR. ENTRADA | CQ18: HR. SALIDA | CR18: SOLICITUD DEL SUPERVISOR | CS18: HRS. LAB. | CT18: TARDANZA (MIN.) | CU18: L - V (MIN. EXTRA) | CV18: SAB. - DOM. EXTRA (MIN.) | CW18: ASISTENCIA DIARIA | CY18: HR. ENTRADA | CZ18: HR. SALIDA | DA18: SOLICITUD DEL SUPERVISOR | DB18: HRS. LAB. | DC18: TARDANZA (MIN.) | DD18: L - V (MIN. EXTRA) | DE18: SAB. - DOM. EXTRA (MIN.) | DF18: ASISTENCIA DIARIA | DH18: HR. ENTRADA | DI18: HR. SALIDA | DJ18: SOLICITUD DEL SUPERVISOR | DK18: HRS. LAB. | DL18: TARDANZA (MIN.) | DM18: L - V (MIN. EXTRA) | DN18: SAB. - DOM. EXTRA (MIN.) | DO18: ASISTENCIA DIARIA | DQ18: HR. ENTRADA | DR18: HR. SALIDA | DS18: SOLICITUD DEL SUPERVISOR | DT18: HRS. LAB. | DU18: TARDANZA (MIN.) | DV18: L - V (MIN. EXTRA) | DW18: SAB. - DOM. EXTRA (MIN.) | DX18: ASISTENCIA DIARIA | DZ18: HR. ENTRADA | EA18: HR. SALIDA | EB18: SOLICITUD DEL SUPERVISOR | EC18: HRS. LAB. | ED18: TARDANZA (MIN.) | EE18: L - V (MIN. EXTRA) | EF18: SAB. - DOM. EXTRA (MIN.) | EG18: ASISTENCIA DIARIA
A19: 1 | B19: ='1RA QUINCENA JUNIO 26'!B10 -> CISNEROS PACOTAYPE KEVIN | C19: 2 | G19: =IF(OR(K19="VACACIONES",K19="FALTA",K19="LICENCIA",D19="",E19=""),"",IF(WEEKDAY($D$17,2)>5,E19-D19,IF(F19="NO",MIN(E19,CHOOSE($C19,$C$3,$C$4))-MAX(D19,CHOOSE($C19,$B$3,$B$4))-CHOOSE($C19,$F$3,$F$4),E19-D19-CHOOSE($C19,$F$3,$F$4)))) | H19: =IF(OR(K19="VACACIONES",K19="FALTA",K19="LICENCIA",D19="",E19="",WEEKDAY($D$17,2)>5),"", MAX(0,CHOOSE($C19,$H$3,$H$4)-(G19*1440)) ) | I19: =IF(OR(K19="VACACIONES",K19="FALTA",K19="LICENCIA",D19="",E19="",F19="NO",WEEKDAY($D$17,2)>5),"",MAX(0,IF(F19="SI", (G19*1440)-CHOOSE($C19,$H$3,$H$4) ))) | J19: =IF(OR(K19="VACACIONES",K19="FALTA",K19="LICENCIA",D19="",E19="",WEEKDAY($D$17,2)<=5),"",IF(WEEKDAY($D$17,2)>5,(G19*1440))) | K19: FALTA | P19: =IF(OR(T19="VACACIONES",T19="FALTA",T19="LICENCIA",M19="",N19=""),"",IF(WEEKDAY($M$17,2)>5,N19-M19,IF(O19="NO",MIN(N19,CHOOSE($C19,$C$3,$C$4))-MAX(M19,CHOOSE($C19,$B$3,$B$4))-CHOOSE($C19,$F$3,$F$4),N19-M19-CHOOSE($C19,$F$3,$F$4)))) | Q19: =IF(OR(T19="VACACIONES",T19="FALTA",T19="LICENCIA",M19="",N19="",WEEKDAY($M$17,2)>5),"", MAX(0,CHOOSE($C19,$H$3,$H$4)-(P19*1440)) ) | R19: =IF(OR(T19="VACACIONES",T19="FALTA",T19="LICENCIA",M19="",N19="",O19="NO",WEEKDAY($M$17,2)>5),"",MAX(0,IF(O19="SI", (P19*1440)-CHOOSE($C19,$H$3,$H$4) ))) | S19: =IF(OR(T19="VACACIONES",T19="FALTA",T19="LICENCIA",M19="",N19="",WEEKDAY($M$17,2)<=5),"",IF(WEEKDAY($M$17,2)>5,(P19*1440))) | T19: FALTA | Y19: =IF(OR(AC19="VACACIONES",AC19="FALTA",AC19="LICENCIA",V19="",W19=""),"",IF(WEEKDAY($V$17,2)>5,W19-V19,IF(X19="NO",MIN(W19,CHOOSE($C19,$C$3,$C$4))-MAX(V19,CHOOSE($C19,$B$3,$B$4))-CHOOSE($C19,$F$3,$F$4),W19-V19-CHOOSE($C19,$F$3,$F$4)))) | Z19: =IF(OR(AC19="VACACIONES",AC19="FALTA",AC19="LICENCIA",V19="",W19="",WEEKDAY($V$17,2)>5),"", MAX(0,CHOOSE($C19,$H$3,$H$4)-(Y19*1440)) ) | AA19: =IF(OR(AC19="VACACIONES",AC19="FALTA",AC19="LICENCIA",V19="",W19="",X19="NO",WEEKDAY($V$17,2)>5),"",MAX(0,IF(X19="SI", (Y19*1440)-CHOOSE($C19,$H$3,$H$4) ))) | AB19: =IF(OR(AC19="VACACIONES",AC19="FALTA",AC19="LICENCIA",V19="",W19="",WEEKDAY($V$17,2)<=5),"",IF(WEEKDAY($V$17,2)>5,(Y19*1440))) | AC19: FALTA | AH19: =IF(OR(AL19="VACACIONES",AL19="FALTA",AL19="LICENCIA",AE19="",AF19=""),"",IF(WEEKDAY($AE$17,2)>5,AF19-AE19,IF(AG19="NO",MIN(AF19,CHOOSE($C19,$C$3,$C$4))-MAX(AE19,CHOOSE($C19,$B$3,$B$4))-CHOOSE($C19,$F$3,$F$4),AF19-AE19-CHOOSE($C19,$F$3,$F$4)))) | AI19: =IF(OR(AL19="VACACIONES",AL19="FALTA",AL19="LICENCIA",AE19="",AF19="",WEEKDAY($AE$17,2)>5),"", MAX(0,CHOOSE($C19,$H$3,$H$4)-(AH19*1440)) ) | AJ19: =IF(OR(AL19="VACACIONES",AL19="FALTA",AL19="LICENCIA",AE19="",AF19="",AG19="NO",WEEKDAY($AE$17,2)>5),"",MAX(0,IF(AG19="SI", (AH19*1440)-CHOOSE($C19,$H$3,$H$4) ))) | AK19: =IF(OR(AL19="VACACIONES",AL19="FALTA",AL19="LICENCIA",AE19="",AF19="",WEEKDAY($AE$17,2)<=5),"",IF(WEEKDAY($AE$17,2)>5,(AH19*1440))) | AL19: FALTA | AQ19: =IF(OR(AU19="VACACIONES",AU19="FALTA",AU19="LICENCIA",AN19="",AO19=""),"",IF(WEEKDAY($AN$17,2)>5,AO19-AN19,IF(AP19="NO",MIN(AO19,CHOOSE($C19,$C$3,$C$4))-MAX(AN19,CHOOSE($C19,$B$3,$B$4))-CHOOSE($C19,$F$3,$F$4),AO19-AN19-CHOOSE($C19,$F$3,$F$4)))) | AR19: =IF(OR(AU19="VACACIONES",AU19="FALTA",AU19="LICENCIA",AN19="",AO19="",WEEKDAY($AN$17,2)>5),"", MAX(0,CHOOSE($C19,$H$3,$H$4)-(AQ19*1440)) ) | AS19: =IF(OR(AU19="VACACIONES",AU19="FALTA",AU19="LICENCIA",AN19="",AO19="",AP19="NO",WEEKDAY($AN$17,2)>5),"",MAX(0,IF(AP19="SI", (AQ19*1440)-CHOOSE($C19,$H$3,$H$4) ))) | AT19: =IF(OR(AU19="VACACIONES",AU19="FALTA",AU19="LICENCIA",AN19="",AO19="",WEEKDAY($AN$17,2)<=5),"",IF(WEEKDAY($AN$17,2)>5,(AQ19*1440))) | AU19: FALTA | AZ19: =IF(OR(BD19="VACACIONES",BD19="FALTA",BD19="LICENCIA",AW19="",AX19=""),"",IF(WEEKDAY($AW$17,2)>5,AX19-AW19,IF(AY19="NO",MIN(AX19,CHOOSE($C19,$C$3,$C$4))-MAX(AW19,CHOOSE($C19,$B$3,$B$4))-CHOOSE($C19,$F$3,$F$4),AX19-AW19-CHOOSE($C19,$F$3,$F$4)))) | BA19: =IF(OR(BD19="VACACIONES",BD19="FALTA",BD19="LICENCIA",AW19="",AX19="",WEEKDAY($AW$17,2)>5),"", MAX(0,CHOOSE($C19,$H$3,$H$4)-(AZ19*1440)) ) | BB19: =IF(OR(BD19="VACACIONES",BD19="FALTA",BD19="LICENCIA",AW19="",AX19="",AY19="NO",WEEKDAY($AW$17,2)>5),"",MAX(0,IF(AY19="SI", (AZ19*1440)-CHOOSE($C19,$H$3,$H$4) ))) | BC19: =IF(OR(BD19="VACACIONES",BD19="FALTA",BD19="LICENCIA",AW19="",AX19="",WEEKDAY($AW$17,2)<=5),"",IF(WEEKDAY($AW$17,2)>5,(AZ19*1440))) | BD19: FALTA | BI19: =IF(OR(BM19="VACACIONES",BM19="FALTA",BM19="LICENCIA",BF19="",BG19=""),"",IF(WEEKDAY($BF$17,2)>5,BG19-BF19,IF(BH19="NO",MIN(BG19,CHOOSE($C19,$C$3,$C$4))-MAX(BF19,CHOOSE($C19,$B$3,$B$4))-CHOOSE($C19,$F$3,$F$4),BG19-BF19-CHOOSE($C19,$F$3,$F$4)))) | BJ19: =IF(OR(BM19="VACACIONES",BM19="FALTA",BM19="LICENCIA",BF19="",BG19="",WEEKDAY($BF$17,2)>5),"", MAX(0,CHOOSE($C19,$H$3,$H$4)-(BI19*1440)) ) | BK19: =IF(OR(BM19="VACACIONES",BM19="FALTA",BM19="LICENCIA",BF19="",BG19="",BH19="NO",WEEKDAY($BF$17,2)>5),"",MAX(0,IF(BH19="SI", (BI19*1440)-CHOOSE($C19,$H$3,$H$4) ))) | BL19: =IF(OR(BM19="VACACIONES",BM19="FALTA",BM19="LICENCIA",BF19="",BG19="",WEEKDAY($BF$17,2)<=5),"",IF(WEEKDAY($BF$17,2)>5,(BI19*1440))) | BM19: FALTA | BO19: 0.36180556 | BP19: 0.78333333 | BQ19: SI | BR19: =IF(OR(BV19="VACACIONES",BV19="FALTA",BV19="LICENCIA",BO19="",BP19=""),"",IF(WEEKDAY($BO$17,2)>5,BP19-BO19,IF(BQ19="NO",MIN(BP19,CHOOSE($C19,$C$3,$C$4))-MAX(BO19,CHOOSE($C19,$B$3,$B$4))-CHOOSE($C19,$F$3,$F$4),BP19-BO19-CHOOSE($C19,$F$3,$F$4)))) -> 0.37986111 | BS19: =IF(OR(BV19="VACACIONES",BV19="FALTA",BV19="LICENCIA",BO19="",BP19="",WEEKDAY($BO$17,2)>5),"", MAX(0,CHOOSE($C19,$H$3,$H$4)-(BR19*1440)) ) -> 0 | BT19: =IF(OR(BV19="VACACIONES",BV19="FALTA",BV19="LICENCIA",BO19="",BP19="",BQ19="NO",WEEKDAY($BO$17,2)>5),"",MAX(0,IF(BQ19="SI", (BR19*1440)-CHOOSE($C19,$H$3,$H$4) ))) -> 7 | BU19: =IF(OR(BV19="VACACIONES",BV19="FALTA",BV19="LICENCIA",BO19="",BP19="",WEEKDAY($BO$17,2)<=5),"",IF(WEEKDAY($BO$17,2)>5,(BR19*1440))) | BX19: 0.36666667 | BY19: 0.83333333 | BZ19: SI | CA19: =IF(OR(CE19="VACACIONES",CE19="FALTA",CE19="LICENCIA",BX19="",BY19=""),"",IF(WEEKDAY($BX$17,2)>5,BY19-BX19,IF(BZ19="NO",MIN(BY19,CHOOSE($C19,$C$3,$C$4))-MAX(BX19,CHOOSE($C19,$B$3,$B$4))-CHOOSE($C19,$F$3,$F$4),BY19-BX19-CHOOSE($C19,$F$3,$F$4)))) -> 0.425 | CB19: =IF(OR(CE19="VACACIONES",CE19="FALTA",CE19="LICENCIA",BX19="",BY19="",WEEKDAY($BX$17,2)>5),"", MAX(0,CHOOSE($C19,$H$3,$H$4)-(CA19*1440)) ) -> 0 | CC19: =IF(OR(CE19="VACACIONES",CE19="FALTA",CE19="LICENCIA",BX19="",BY19="",BZ19="NO",WEEKDAY($BX$17,2)>5),"",MAX(0,IF(BZ19="SI", (CA19*1440)-CHOOSE($C19,$H$3,$H$4) ))) -> 72 | CD19: =IF(OR(CE19="VACACIONES",CE19="FALTA",CE19="LICENCIA",BX19="",BY19="",WEEKDAY($BX$17,2)<=5),"",IF(WEEKDAY($BX$17,2)>5,(CA19*1440))) | CG19: 0.375 | CH19: 0.80416667 | CI19: SI | CJ19: =IF(OR(CN19="VACACIONES",CN19="FALTA",CN19="LICENCIA",CG19="",CH19=""),"",IF(WEEKDAY($CG$17,2)>5,CH19-CG19,IF(CI19="NO",MIN(CH19,CHOOSE($C19,$C$3,$C$4))-MAX(CG19,CHOOSE($C19,$B$3,$B$4))-CHOOSE($C19,$F$3,$F$4),CH19-CG19-CHOOSE($C19,$F$3,$F$4)))) -> 0.3875 | CK19: =IF(OR(CN19="VACACIONES",CN19="FALTA",CN19="LICENCIA",CG19="",CH19="",WEEKDAY($CG$17,2)>5),"", MAX(0,CHOOSE($C19,$H$3,$H$4)-(CJ19*1440)) ) -> 0 | CL19: =IF(OR(CN19="VACACIONES",CN19="FALTA",CN19="LICENCIA",CG19="",CH19="",CI19="NO",WEEKDAY($CG$17,2)>5),"",MAX(0,IF(CI19="SI", (CJ19*1440)-CHOOSE($C19,$H$3,$H$4) ))) -> 18 | CM19: =IF(OR(CN19="VACACIONES",CN19="FALTA",CN19="LICENCIA",CG19="",CH19="",WEEKDAY($CG$17,2)<=5),"",IF(WEEKDAY($CG$17,2)>5,(CJ19*1440))) | CP19: 0.39236111 | CQ19: 0.82222222 | CR19: SI | CS19: =IF(OR(CW19="VACACIONES",CW19="FALTA",CW19="LICENCIA",CP19="",CQ19=""),"",IF(WEEKDAY($CP$17,2)>5,CQ19-CP19,IF(CR19="NO",MIN(CQ19,CHOOSE($C19,$C$3,$C$4))-MAX(CP19,CHOOSE($C19,$B$3,$B$4))-CHOOSE($C19,$F$3,$F$4),CQ19-CP19-CHOOSE($C19,$F$3,$F$4)))) -> 0.38819444 | CT19: =IF(OR(CW19="VACACIONES",CW19="FALTA",CW19="LICENCIA",CP19="",CQ19="",WEEKDAY($CP$17,2)>5),"", MAX(0,CHOOSE($C19,$H$3,$H$4)-(CS19*1440)) ) -> 0 | CU19: =IF(OR(CW19="VACACIONES",CW19="FALTA",CW19="LICENCIA",CP19="",CQ19="",CR19="NO",WEEKDAY($CP$17,2)>5),"",MAX(0,IF(CR19="SI", (CS19*1440)-CHOOSE($C19,$H$3,$H$4) ))) -> 19 | CV19: =IF(OR(CW19="VACACIONES",CW19="FALTA",CW19="LICENCIA",CP19="",CQ19="",WEEKDAY($CP$17,2)<=5),"",IF(WEEKDAY($CP$17,2)>5,(CS19*1440))) | CY19: 0.37361111 | CZ19: 0.80902778 | DA19: SI | DB19: =IF(OR(DF19="VACACIONES",DF19="FALTA",DF19="LICENCIA",CY19="",CZ19=""),"",IF(WEEKDAY($CY$17,2)>5,CZ19-CY19,IF(DA19="NO",MIN(CZ19,CHOOSE($C19,$C$3,$C$4))-MAX(CY19,CHOOSE($C19,$B$3,$B$4))-CHOOSE($C19,$F$3,$F$4),CZ19-CY19-CHOOSE($C19,$F$3,$F$4)))) -> 0.39375 | DC19: =IF(OR(DF19="VACACIONES",DF19="FALTA",DF19="LICENCIA",CY19="",CZ19="",WEEKDAY($CY$17,2)>5),"", MAX(0,CHOOSE($C19,$H$3,$H$4)-(DB19*1440)) ) -> 0 | DD19: =IF(OR(DF19="VACACIONES",DF19="FALTA",DF19="LICENCIA",CY19="",CZ19="",DA19="NO",WEEKDAY($CY$17,2)>5),"",MAX(0,IF(DA19="SI", (DB19*1440)-CHOOSE($C19,$H$3,$H$4) ))) -> 27 | DE19: =IF(OR(DF19="VACACIONES",DF19="FALTA",DF19="LICENCIA",CY19="",CZ19="",WEEKDAY($CY$17,2)<=5),"",IF(WEEKDAY($CY$17,2)>5,(DB19*1440))) | DK19: =IF(OR(DO19="VACACIONES",DO19="FALTA",DO19="LICENCIA",DH19="",DI19=""),"",IF(WEEKDAY($DH$17,2)>5,DI19-DH19,IF(DJ19="NO",MIN(DI19,CHOOSE($C19,$C$3,$C$4))-MAX(DH19,CHOOSE($C19,$B$3,$B$4))-CHOOSE($C19,$F$3,$F$4),DI19-DH19-CHOOSE($C19,$F$3,$F$4)))) | DL19: =IF(OR(DO19="VACACIONES",DO19="FALTA",DO19="LICENCIA",DH19="",DI19="",WEEKDAY($DH$17,2)>5),"", MAX(0,CHOOSE($C19,$H$3,$H$4)-(DK19*1440)) ) | DM19: =IF(OR(DO19="VACACIONES",DO19="FALTA",DO19="LICENCIA",DH19="",DI19="",DJ19="NO",WEEKDAY($DH$17,2)>5),"",MAX(0,IF(DJ19="SI", (DK19*1440)-CHOOSE($C19,$H$3,$H$4) ))) | DN19: =IF(OR(DO19="VACACIONES",DO19="FALTA",DO19="LICENCIA",DH19="",DI19="",WEEKDAY($DH$17,2)<=5),"",IF(WEEKDAY($DH$17,2)>5,(DK19*1440))) | DT19: =IF(OR(DX19="VACACIONES",DX19="FALTA",DX19="LICENCIA",DQ19="",DR19=""),"",IF(WEEKDAY($DQ$17,2)>5,DR19-DR19,IF(DS19="NO",MIN(DR19,CHOOSE($C19,$C$3,$C$4))-MAX(DQ19,CHOOSE($C19,$B$3,$B$4))-CHOOSE($C19,$F$3,$F$4),DR19-DQ19-CHOOSE($C19,$F$3,$F$4)))) | DU19: =IF(OR(DX19="VACACIONES",DX19="FALTA",DX19="LICENCIA",DQ19="",DR19="",WEEKDAY($DQ$17,2)>5),"", MAX(0,CHOOSE($C19,$H$3,$H$4)-(DT19*1440)) ) | DV19: =IF(OR(DX19="VACACIONES",DX19="FALTA",DX19="LICENCIA",DQ19="",DR19="",DS19="NO",WEEKDAY($DQ$17,2)>5),"",MAX(0,IF(DS19="SI", (DT19*1440)-CHOOSE($C19,$H$3,$H$4) ))) | DW19: =IF(OR(DX19="VACACIONES",DX19="FALTA",DX19="LICENCIA",DQ19="",DR19="",WEEKDAY($DQ$17,2)<=5),"",IF(WEEKDAY($DQ$17,2)>5,(DT19*1440))) | DZ19: 0.33333333 | EA19: 0.7875 | EB19: NO | EC19: =IF(OR(EG19="VACACIONES",EG19="FALTA",EG19="LICENCIA",DZ19="",EA19=""),"",IF(WEEKDAY($CY$17,2)>5,EA19-DZ19,IF(EB19="NO",MIN(EA19,CHOOSE($C19,$C$3,$C$4))-MAX(DZ19,CHOOSE($C19,$B$3,$B$4))-CHOOSE($C19,$F$3,$F$4),EA19-DZ19-CHOOSE($C19,$F$3,$F$4)))) -> 0.375 | ED19: =IF(OR(EG19="VACACIONES",EG19="FALTA",EG19="LICENCIA",DZ19="",EA19="",WEEKDAY($CY$17,2)>5),"", MAX(0,CHOOSE($C19,$H$3,$H$4)-(EC19*1440)) ) -> 0 | EE19: =IF(OR(EG19="VACACIONES",EG19="FALTA",EG19="LICENCIA",DZ19="",EA19="",EB19="NO",WEEKDAY($CY$17,2)>5),"",MAX(0,IF(EB19="SI", (EC19*1440)-CHOOSE($C19,$H$3,$H$4) ))) | EF19: =IF(OR(EG19="VACACIONES",EG19="FALTA",EG19="LICENCIA",DZ19="",EA19="",WEEKDAY($CY$17,2)<=5),"",IF(WEEKDAY($CY$17,2)>5,(EC19*1440))) | EK19: =SUM(H19,Q19,Z19,AI19,AR19,BA19,BJ19,BS19,CB19,CK19,CT19,DC19,DL19,DU19,ED19) -> 0 | EL19: 0 | EM19: =COUNTIF(I19,">0")+COUNTIF(J19,">0")+COUNTIF(R19,">0")+COUNTIF(S19,">0")++COUNTIF(AA19,">0")+COUNTIF(AB19,">0")+COUNTIF(AJ19,">0")+COUNTIF(AK19,">0")+COUNTIF(AS19,">0")+COUNTIF(AT19,">0")+COUNTIF(BB19,">0")+COUNTIF(BC19,">0")+COUNTIF(BK19,">0")+COUNTIF(BL19,">0")+COUNTIF(BT19,">0")+COUNTIF(BU19,">0")+COUNTIF(CC19,">0")+COUNTIF(CD19,">0")+COUNTIF(CL19,">0")+COUNTIF(CM19,">0")+COUNTIF(CU19,">0")+COUNTIF(CV19,">0")+COUNTIF(DD19,">0")+COUNTIF(DE19,">0")+COUNTIF(DM19,">0")+COUNTIF(DN19,">0")+COUNTIF(DV19,">0")+COUNTIF(DW19,">0")+COUNTIF(EE19,">0")+COUNTIF(EF19,">0") -> 5 | EN19: =COUNTIF(D19:EG19,"FALTA") -> 7 | EO19: =15-EN19 -> 8 | EP19: =COUNTIF(D19:EG19,"TRABAJO SABADO") -> 0 | EQ19: =COUNTIF(D19:EG19,"TRABAJO DOMINGO")+COUNTIF(D19:EG19,"TRABAJO FERIADO")+(COUNTIF(D19:EG19,"TRABAJO 1RO MAYO")*2)+((COUNTIF(D21:EG21,"TRABAJO 1RO MAYO EN SU DIA LIBRE")*2)*2) -> 0 | ER19: =COUNTIF(D19:EG19,"VACACIONES") -> 0 | ES19: =COUNTIF(D19:EG19,"LICENCIA") -> 0
A20: =A19+1 -> 2 | B20: ='1RA QUINCENA JUNIO 26'!B11 -> CISNEROS SUMA, ANDRES JUAN | C20: 1 | D20: 0.30763889 | E20: 0.75 | F20: NO | G20: =IF(OR(K20="VACACIONES",K20="FALTA",K20="LICENCIA",D20="",E20=""),"",IF(WEEKDAY($D$17,2)>5,E20-D20,IF(F20="NO",MIN(E20,CHOOSE($C20,$C$3,$C$4))-MAX(D20,CHOOSE($C20,$B$3,$B$4))-CHOOSE($C20,$F$3,$F$4),E20-D20-CHOOSE($C20,$F$3,$F$4)))) -> 0.40069444 | H20: =IF(OR(K20="VACACIONES",K20="FALTA",K20="LICENCIA",D20="",E20="",WEEKDAY($D$17,2)>5),"", MAX(0,CHOOSE($C20,$H$3,$H$4)-(G20*1440)) ) -> 0 | I20: =IF(OR(K20="VACACIONES",K20="FALTA",K20="LICENCIA",D20="",E20="",F20="NO",WEEKDAY($D$17,2)>5),"",MAX(0,IF(F20="SI", (G20*1440)-CHOOSE($C20,$H$3,$H$4) ))) | J20: =IF(OR(K20="VACACIONES",K20="FALTA",K20="LICENCIA",D20="",E20="",WEEKDAY($D$17,2)<=5),"",IF(WEEKDAY($D$17,2)>5,(G20*1440))) | M20: 0.30763889 | N20: 0.75 | O20: NO | P20: =IF(OR(T20="VACACIONES",T20="FALTA",T20="LICENCIA",M20="",N20=""),"",IF(WEEKDAY($M$17,2)>5,N20-M20,IF(O20="NO",MIN(N20,CHOOSE($C20,$C$3,$C$4))-MAX(M20,CHOOSE($C20,$B$3,$B$4))-CHOOSE($C20,$F$3,$F$4),N20-M20-CHOOSE($C20,$F$3,$F$4)))) -> 0.40069444 | Q20: =IF(OR(T20="VACACIONES",T20="FALTA",T20="LICENCIA",M20="",N20="",WEEKDAY($M$17,2)>5),"", MAX(0,CHOOSE($C20,$H$3,$H$4)-(P20*1440)) ) -> 0 | R20: =IF(OR(T20="VACACIONES",T20="FALTA",T20="LICENCIA",M20="",N20="",O20="NO",WEEKDAY($M$17,2)>5),"",MAX(0,IF(O20="SI", (P20*1440)-CHOOSE($C20,$H$3,$H$4) ))) | S20: =IF(OR(T20="VACACIONES",T20="FALTA",T20="LICENCIA",M20="",N20="",WEEKDAY($M$17,2)<=5),"",IF(WEEKDAY($M$17,2)>5,(P20*1440))) | V20: 0.30763889 | W20: 0.75 | X20: NO | Y20: =IF(OR(AC20="VACACIONES",AC20="FALTA",AC20="LICENCIA",V20="",W20=""),"",IF(WEEKDAY($V$17,2)>5,W20-V20,IF(X20="NO",MIN(W20,CHOOSE($C20,$C$3,$C$4))-MAX(V20,CHOOSE($C20,$B$3,$B$4))-CHOOSE($C20,$F$3,$F$4),W20-V20-CHOOSE($C20,$F$3,$F$4)))) -> 0.40069444 | Z20: =IF(OR(AC20="VACACIONES",AC20="FALTA",AC20="LICENCIA",V20="",W20="",WEEKDAY($V$17,2)>5),"", MAX(0,CHOOSE($C20,$H$3,$H$4)-(Y20*1440)) ) -> 0 | AA20: =IF(OR(AC20="VACACIONES",AC20="FALTA",AC20="LICENCIA",V20="",W20="",X20="NO",WEEKDAY($V$17,2)>5),"",MAX(0,IF(X20="SI", (Y20*1440)-CHOOSE($C20,$H$3,$H$4) ))) | AB20: =IF(OR(AC20="VACACIONES",AC20="FALTA",AC20="LICENCIA",V20="",W20="",WEEKDAY($V$17,2)<=5),"",IF(WEEKDAY($V$17,2)>5,(Y20*1440))) | AE20: 0.30763889 | AF20: 0.75 | AG20: NO | AH20: =IF(OR(AL20="VACACIONES",AL20="FALTA",AL20="LICENCIA",AE20="",AF20=""),"",IF(WEEKDAY($AE$17,2)>5,AF20-AE20,IF(AG20="NO",MIN(AF20,CHOOSE($C20,$C$3,$C$4))-MAX(AE20,CHOOSE($C20,$B$3,$B$4))-CHOOSE($C20,$F$3,$F$4),AF20-AE20-CHOOSE($C20,$F$3,$F$4)))) -> 0.40069444 | AI20: =IF(OR(AL20="VACACIONES",AL20="FALTA",AL20="LICENCIA",AE20="",AF20="",WEEKDAY($AE$17,2)>5),"", MAX(0,CHOOSE($C20,$H$3,$H$4)-(AH20*1440)) ) -> 0 | AJ20: =IF(OR(AL20="VACACIONES",AL20="FALTA",AL20="LICENCIA",AE20="",AF20="",AG20="NO",WEEKDAY($AE$17,2)>5),"",MAX(0,IF(AG20="SI", (AH20*1440)-CHOOSE($C20,$H$3,$H$4) ))) | AK20: =IF(OR(AL20="VACACIONES",AL20="FALTA",AL20="LICENCIA",AE20="",AF20="",WEEKDAY($AE$17,2)<=5),"",IF(WEEKDAY($AE$17,2)>5,(AH20*1440))) | AN20: 0.30763889 | AO20: 0.75 | AP20: NO | AQ20: =IF(OR(AU20="VACACIONES",AU20="FALTA",AU20="LICENCIA",AN20="",AO20=""),"",IF(WEEKDAY($AN$17,2)>5,AO20-AN20,IF(AP20="NO",MIN(AO20,CHOOSE($C20,$C$3,$C$4))-MAX(AN20,CHOOSE($C20,$B$3,$B$4))-CHOOSE($C20,$F$3,$F$4),AO20-AN20-CHOOSE($C20,$F$3,$F$4)))) -> 0.40069444 | AR20: =IF(OR(AU20="VACACIONES",AU20="FALTA",AU20="LICENCIA",AN20="",AO20="",WEEKDAY($AN$17,2)>5),"", MAX(0,CHOOSE($C20,$H$3,$H$4)-(AQ20*1440)) ) -> 0 | AS20: =IF(OR(AU20="VACACIONES",AU20="FALTA",AU20="LICENCIA",AN20="",AO20="",AP20="NO",WEEKDAY($AN$17,2)>5),"",MAX(0,IF(AP20="SI", (AQ20*1440)-CHOOSE($C20,$H$3,$H$4) ))) | AT20: =IF(OR(AU20="VACACIONES",AU20="FALTA",AU20="LICENCIA",AN20="",AO20="",WEEKDAY($AN$17,2)<=5),"",IF(WEEKDAY($AN$17,2)>5,(AQ20*1440))) | AZ20: =IF(OR(BD20="VACACIONES",BD20="FALTA",BD20="LICENCIA",AW20="",AX20=""),"",IF(WEEKDAY($AW$17,2)>5,AX20-AW20,IF(AY20="NO",MIN(AX20,CHOOSE($C20,$C$3,$C$4))-MAX(AW20,CHOOSE($C20,$B$3,$B$4))-CHOOSE($C20,$F$3,$F$4),AX20-AW20-CHOOSE($C20,$F$3,$F$4)))) | BA20: =IF(OR(BD20="VACACIONES",BD20="FALTA",BD20="LICENCIA",AW20="",AX20="",WEEKDAY($AW$17,2)>5),"", MAX(0,CHOOSE($C20,$H$3,$H$4)-(AZ20*1440)) ) | BB20: =IF(OR(BD20="VACACIONES",BD20="FALTA",BD20="LICENCIA",AW20="",AX20="",AY20="NO",WEEKDAY($AW$17,2)>5),"",MAX(0,IF(AY20="SI", (AZ20*1440)-CHOOSE($C20,$H$3,$H$4) ))) | BC20: =IF(OR(BD20="VACACIONES",BD20="FALTA",BD20="LICENCIA",AW20="",AX20="",WEEKDAY($AW$17,2)<=5),"",IF(WEEKDAY($AW$17,2)>5,(AZ20*1440))) | BI20: =IF(OR(BM20="VACACIONES",BM20="FALTA",BM20="LICENCIA",BF20="",BG20=""),"",IF(WEEKDAY($BF$17,2)>5,BG20-BF20,IF(BH20="NO",MIN(BG20,CHOOSE($C20,$C$3,$C$4))-MAX(BF20,CHOOSE($C20,$B$3,$B$4))-CHOOSE($C20,$F$3,$F$4),BG20-BF20-CHOOSE($C20,$F$3,$F$4)))) | BJ20: =IF(OR(BM20="VACACIONES",BM20="FALTA",BM20="LICENCIA",BF20="",BG20="",WEEKDAY($BF$17,2)>5),"", MAX(0,CHOOSE($C20,$H$3,$H$4)-(BI20*1440)) ) | BK20: =IF(OR(BM20="VACACIONES",BM20="FALTA",BM20="LICENCIA",BF20="",BG20="",BH20="NO",WEEKDAY($BF$17,2)>5),"",MAX(0,IF(BH20="SI", (BI20*1440)-CHOOSE($C20,$H$3,$H$4) ))) | BL20: =IF(OR(BM20="VACACIONES",BM20="FALTA",BM20="LICENCIA",BF20="",BG20="",WEEKDAY($BF$17,2)<=5),"",IF(WEEKDAY($BF$17,2)>5,(BI20*1440))) | BO20: 0.30763889 | BP20: 0.75 | BQ20: NO | BR20: =IF(OR(BV20="VACACIONES",BV20="FALTA",BV20="LICENCIA",BO20="",BP20=""),"",IF(WEEKDAY($BO$17,2)>5,BP20-BO20,IF(BQ20="NO",MIN(BP20,CHOOSE($C20,$C$3,$C$4))-MAX(BO20,CHOOSE($C20,$B$3,$B$4))-CHOOSE($C20,$F$3,$F$4),BP20-BO20-CHOOSE($C20,$F$3,$F$4)))) -> 0.40069444 | BS20: =IF(OR(BV20="VACACIONES",BV20="FALTA",BV20="LICENCIA",BO20="",BP20="",WEEKDAY($BO$17,2)>5),"", MAX(0,CHOOSE($C20,$H$3,$H$4)-(BR20*1440)) ) -> 0 | BT20: =IF(OR(BV20="VACACIONES",BV20="FALTA",BV20="LICENCIA",BO20="",BP20="",BQ20="NO",WEEKDAY($BO$17,2)>5),"",MAX(0,IF(BQ20="SI", (BR20*1440)-CHOOSE($C20,$H$3,$H$4) ))) | BU20: =IF(OR(BV20="VACACIONES",BV20="FALTA",BV20="LICENCIA",BO20="",BP20="",WEEKDAY($BO$17,2)<=5),"",IF(WEEKDAY($BO$17,2)>5,(BR20*1440))) | BX20: 0.30763889 | BY20: 0.75 | BZ20: NO | CA20: =IF(OR(CE20="VACACIONES",CE20="FALTA",CE20="LICENCIA",BX20="",BY20=""),"",IF(WEEKDAY($BX$17,2)>5,BY20-BX20,IF(BZ20="NO",MIN(BY20,CHOOSE($C20,$C$3,$C$4))-MAX(BX20,CHOOSE($C20,$B$3,$B$4))-CHOOSE($C20,$F$3,$F$4),BY20-BX20-CHOOSE($C20,$F$3,$F$4)))) -> 0.40069444 | CB20: =IF(OR(CE20="VACACIONES",CE20="FALTA",CE20="LICENCIA",BX20="",BY20="",WEEKDAY($BX$17,2)>5),"", MAX(0,CHOOSE($C20,$H$3,$H$4)-(CA20*1440)) ) -> 0 | CC20: =IF(OR(CE20="VACACIONES",CE20="FALTA",CE20="LICENCIA",BX20="",BY20="",BZ20="NO",WEEKDAY($BX$17,2)>5),"",MAX(0,IF(BZ20="SI", (CA20*1440)-CHOOSE($C20,$H$3,$H$4) ))) | CD20: =IF(OR(CE20="VACACIONES",CE20="FALTA",CE20="LICENCIA",BX20="",BY20="",WEEKDAY($BX$17,2)<=5),"",IF(WEEKDAY($BX$17,2)>5,(CA20*1440))) | CG20: 0.30763889 | CH20: 0.75 | CI20: NO | CJ20: =IF(OR(CN20="VACACIONES",CN20="FALTA",CN20="LICENCIA",CG20="",CH20=""),"",IF(WEEKDAY($CG$17,2)>5,CH20-CG20,IF(CI20="NO",MIN(CH20,CHOOSE($C20,$C$3,$C$4))-MAX(CG20,CHOOSE($C20,$B$3,$B$4))-CHOOSE($C20,$F$3,$F$4),CH20-CG20-CHOOSE($C20,$F$3,$F$4)))) -> 0.40069444 | CK20: =IF(OR(CN20="VACACIONES",CN20="FALTA",CN20="LICENCIA",CG20="",CH20="",WEEKDAY($CG$17,2)>5),"", MAX(0,CHOOSE($C20,$H$3,$H$4)-(CJ20*1440)) ) -> 0 | CL20: =IF(OR(CN20="VACACIONES",CN20="FALTA",CN20="LICENCIA",CG20="",CH20="",CI20="NO",WEEKDAY($CG$17,2)>5),"",MAX(0,IF(CI20="SI", (CJ20*1440)-CHOOSE($C20,$H$3,$H$4) ))) | CM20: =IF(OR(CN20="VACACIONES",CN20="FALTA",CN20="LICENCIA",CG20="",CH20="",WEEKDAY($CG$17,2)<=5),"",IF(WEEKDAY($CG$17,2)>5,(CJ20*1440))) | CP20: 0.30763889 | CQ20: 0.75 | CR20: NO | CS20: =IF(OR(CW20="VACACIONES",CW20="FALTA",CW20="LICENCIA",CP20="",CQ20=""),"",IF(WEEKDAY($CP$17,2)>5,CQ20-CP20,IF(CR20="NO",MIN(CQ20,CHOOSE($C20,$C$3,$C$4))-MAX(CP20,CHOOSE($C20,$B$3,$B$4))-CHOOSE($C20,$F$3,$F$4),CQ20-CP20-CHOOSE($C20,$F$3,$F$4)))) -> 0.40069444 | CT20: =IF(OR(CW20="VACACIONES",CW20="FALTA",CW20="LICENCIA",CP20="",CQ20="",WEEKDAY($CP$17,2)>5),"", MAX(0,CHOOSE($C20,$H$3,$H$4)-(CS20*1440)) ) -> 0 | CU20: =IF(OR(CW20="VACACIONES",CW20="FALTA",CW20="LICENCIA",CP20="",CQ20="",CR20="NO",WEEKDAY($CP$17,2)>5),"",MAX(0,IF(CR20="SI", (CS20*1440)-CHOOSE($C20,$H$3,$H$4) ))) | CV20: =IF(OR(CW20="VACACIONES",CW20="FALTA",CW20="LICENCIA",CP20="",CQ20="",WEEKDAY($CP$17,2)<=5),"",IF(WEEKDAY($CP$17,2)>5,(CS20*1440))) | CY20: 0.30763889 | CZ20: 0.75 | DA20: NO | DB20: =IF(OR(DF20="VACACIONES",DF20="FALTA",DF20="LICENCIA",CY20="",CZ20=""),"",IF(WEEKDAY($CY$17,2)>5,CZ20-CY20,IF(DA20="NO",MIN(CZ20,CHOOSE($C20,$C$3,$C$4))-MAX(CY20,CHOOSE($C20,$B$3,$B$4))-CHOOSE($C20,$F$3,$F$4),CZ20-CY20-CHOOSE($C20,$F$3,$F$4)))) -> 0.40069444 | DC20: =IF(OR(DF20="VACACIONES",DF20="FALTA",DF20="LICENCIA",CY20="",CZ20="",WEEKDAY($CY$17,2)>5),"", MAX(0,CHOOSE($C20,$H$3,$H$4)-(DB20*1440)) ) -> 0 | DD20: =IF(OR(DF20="VACACIONES",DF20="FALTA",DF20="LICENCIA",CY20="",CZ20="",DA20="NO",WEEKDAY($CY$17,2)>5),"",MAX(0,IF(DA20="SI", (DB20*1440)-CHOOSE($C20,$H$3,$H$4) ))) | DE20: =IF(OR(DF20="VACACIONES",DF20="FALTA",DF20="LICENCIA",CY20="",CZ20="",WEEKDAY($CY$17,2)<=5),"",IF(WEEKDAY($CY$17,2)>5,(DB20*1440))) | DK20: =IF(OR(DO20="VACACIONES",DO20="FALTA",DO20="LICENCIA",DH20="",DI20=""),"",IF(WEEKDAY($DH$17,2)>5,DI20-DH20,IF(DJ20="NO",MIN(DI20,CHOOSE($C20,$C$3,$C$4))-MAX(DH20,CHOOSE($C20,$B$3,$B$4))-CHOOSE($C20,$F$3,$F$4),DI20-DH20-CHOOSE($C20,$F$3,$F$4)))) | DL20: =IF(OR(DO20="VACACIONES",DO20="FALTA",DO20="LICENCIA",DH20="",DI20="",WEEKDAY($DH$17,2)>5),"", MAX(0,CHOOSE($C20,$H$3,$H$4)-(DK20*1440)) ) | DM20: =IF(OR(DO20="VACACIONES",DO20="FALTA",DO20="LICENCIA",DH20="",DI20="",DJ20="NO",WEEKDAY($DH$17,2)>5),"",MAX(0,IF(DJ20="SI", (DK20*1440)-CHOOSE($C20,$H$3,$H$4) ))) | DN20: =IF(OR(DO20="VACACIONES",DO20="FALTA",DO20="LICENCIA",DH20="",DI20="",WEEKDAY($DH$17,2)<=5),"",IF(WEEKDAY($DH$17,2)>5,(DK20*1440))) | DT20: =IF(OR(DX20="VACACIONES",DX20="FALTA",DX20="LICENCIA",DQ20="",DR20=""),"",IF(WEEKDAY($DQ$17,2)>5,DR20-DR20,IF(DS20="NO",MIN(DR20,CHOOSE($C20,$C$3,$C$4))-MAX(DQ20,CHOOSE($C20,$B$3,$B$4))-CHOOSE($C20,$F$3,$F$4),DR20-DQ20-CHOOSE($C20,$F$3,$F$4)))) | DU20: =IF(OR(DX20="VACACIONES",DX20="FALTA",DX20="LICENCIA",DQ20="",DR20="",WEEKDAY($DQ$17,2)>5),"", MAX(0,CHOOSE($C20,$H$3,$H$4)-(DT20*1440)) ) | DV20: =IF(OR(DX20="VACACIONES",DX20="FALTA",DX20="LICENCIA",DQ20="",DR20="",DS20="NO",WEEKDAY($DQ$17,2)>5),"",MAX(0,IF(DS20="SI", (DT20*1440)-CHOOSE($C20,$H$3,$H$4) ))) | DW20: =IF(OR(DX20="VACACIONES",DX20="FALTA",DX20="LICENCIA",DQ20="",DR20="",WEEKDAY($DQ$17,2)<=5),"",IF(WEEKDAY($DQ$17,2)>5,(DT20*1440))) | DZ20: 0.34930556 | EA20: 0.75 | EB20: NO | EC20: =IF(OR(EG20="VACACIONES",EG20="FALTA",EG20="LICENCIA",DZ20="",EA20=""),"",IF(WEEKDAY($CY$17,2)>5,EA20-DZ20,IF(EB20="NO",MIN(EA20,CHOOSE($C20,$C$3,$C$4))-MAX(DZ20,CHOOSE($C20,$B$3,$B$4))-CHOOSE($C20,$F$3,$F$4),EA20-DZ20-CHOOSE($C20,$F$3,$F$4)))) -> 0.35902778 | ED20: =IF(OR(EG20="VACACIONES",EG20="FALTA",EG20="LICENCIA",DZ20="",EA20="",WEEKDAY($CY$17,2)>5),"", MAX(0,CHOOSE($C20,$H$3,$H$4)-(EC20*1440)) ) -> 60 | EE20: =IF(OR(EG20="VACACIONES",EG20="FALTA",EG20="LICENCIA",DZ20="",EA20="",EB20="NO",WEEKDAY($CY$17,2)>5),"",MAX(0,IF(EB20="SI", (EC20*1440)-CHOOSE($C20,$H$3,$H$4) ))) | EF20: =IF(OR(EG20="VACACIONES",EG20="FALTA",EG20="LICENCIA",DZ20="",EA20="",WEEKDAY($CY$17,2)<=5),"",IF(WEEKDAY($CY$17,2)>5,(EC20*1440))) | EK20: =SUM(H20,Q20,Z20,AI20,AR20,BA20,BJ20,BS20,CB20,CK20,CT20,DC20,DL20,DU20,ED20) -> 60 | EL20: =SUM(I20,J20,R20,S20,AA20,AB20,AJ20,AK20,AS20,AT20,BB20,BC20,BK20,BL20,BT20,BU20,CC20,CD20,CL20,CM20,CU20,CV20,DD20,DE20,DM20,DN20,DV20,DW20,EE20,EF20) -> 0 | EM20: =COUNTIF(I20,">0")+COUNTIF(J20,">0")+COUNTIF(R20,">0")+COUNTIF(S20,">0")++COUNTIF(AA20,">0")+COUNTIF(AB20,">0")+COUNTIF(AJ20,">0")+COUNTIF(AK20,">0")+COUNTIF(AS20,">0")+COUNTIF(AT20,">0")+COUNTIF(BB20,">0")+COUNTIF(BC20,">0")+COUNTIF(BK20,">0")+COUNTIF(BL20,">0")+COUNTIF(BT20,">0")+COUNTIF(BU20,">0")+COUNTIF(CC20,">0")+COUNTIF(CD20,">0")+COUNTIF(CL20,">0")+COUNTIF(CM20,">0")+COUNTIF(CU20,">0")+COUNTIF(CV20,">0")+COUNTIF(DD20,">0")+COUNTIF(DE20,">0")+COUNTIF(DM20,">0")+COUNTIF(DN20,">0")+COUNTIF(DV20,">0")+COUNTIF(DW20,">0")+COUNTIF(EE20,">0")+COUNTIF(EF20,">0") -> 0 | EN20: =COUNTIF(D20:EG20,"FALTA") -> 0 | EO20: =15-EN20 -> 15 | EP20: =COUNTIF(D20:EG20,"TRABAJO SABADO") -> 0 | EQ20: =COUNTIF(D20:EG20,"TRABAJO DOMINGO")+COUNTIF(D20:EG20,"TRABAJO FERIADO")+(COUNTIF(D20:EG20,"TRABAJO 1RO MAYO")*2)+((COUNTIF(D22:EG22,"TRABAJO 1RO MAYO EN SU DIA LIBRE")*2)*2) -> 0 | ER20: =COUNTIF(D20:EG20,"VACACIONES") -> 0 | ES20: =COUNTIF(D20:EG20,"LICENCIA") -> 0
